Workbook

Sheet Figure_6B_6D
A1: 1 | B1: 2 | C1: 3 | D1: 4 | E1: 5 | F1: 6 | G1: 7 | H1: 8 | I1: 9 | J1: 10 | K1: 11 | L1: 12 | M1: 13
A2: Variables -> | B2: EM_Model_HumanCapital_epsiig___yd | C2: EM_Model_HumanCapital_epsicge___yd | D2: EM_Model_HumanCapital_epsiigeff10y___yd | E2: EM_Model_HumanCapital_epsicgeeff10y___yd | F2: EM_Model_HumanCapital_epsiigeff25y___yd | G2: EM_Model_HumanCapital_epsicgeeff25y___yd | H2: EM_Model_HumanCapital_epsiiglow___yd | I2: EM_Model_HumanCapital_epsicgelow___yd | J2: EM_Model_HumanCapital_epsiigeff10ylow___yd | K2: EM_Model_HumanCapital_epsicgeeff10ylow___yd | L2: EM_Model_HumanCapital_epsiigeff25ylow___yd | M2: EM_Model_HumanCapital_epsicgeeff25ylow___yd
A3: Comments ->
A4: Class[Size] -> | B4: Series[201-by-1] | C4: Series[201-by-1] | D4: Series[201-by-1] | E4: Series[201-by-1] | F4: Series[201-by-1] | G4: Series[201-by-1]
A9: 1Q4 | B9: =Results_from_model!N9 -> -0.075 | C9: =Results_from_model!O9 -> 0.182 | D9: =Results_from_model!P9 -> -0.272 | E9: =Results_from_model!Q9 -> 0.492 | F9: =Results_from_model!R9 -> -0.15 | G9: =Results_from_model!S9 -> 0.362 | H9: =Results_from_model!T9 -> -0.075 | I9: =Results_from_model!U9 -> 0.182 | ... M9: =Results_from_model!Y9 -> 0.415
A10: 2Q1 | B10: =Results_from_model!N10 -> 0.046 | C10: =Results_from_model!O10 -> 0.093 | D10: =Results_from_model!P10 -> -0.158 | E10: =Results_from_model!Q10 -> 0.372 | F10: =Results_from_model!R10 -> -0.034 | G10: =Results_from_model!S10 -> 0.259 | H10: =Results_from_model!T10 -> 0.046 | I10: =Results_from_model!U10 -> 0.093 | ... M10: =Results_from_model!Y10 -> 0.308
A11: 2Q2 | B11: =Results_from_model!N11 -> 0.165 | C11: =Results_from_model!O11 -> 0.014 | D11: =Results_from_model!P11 -> -0.04 | E11: =Results_from_model!Q11 -> 0.26 | F11: =Results_from_model!R11 -> 0.083 | G11: =Results_from_model!S11 -> 0.165 | H11: =Results_from_model!T11 -> 0.165 | I11: =Results_from_model!U11 -> 0.014 | ... M11: =Results_from_model!Y11 -> 0.209
A12: 2Q3 | B12: =Results_from_model!N12 -> 0.282 | C12: =Results_from_model!O12 -> -0.054 | D12: =Results_from_model!P12 -> 0.078 | E12: =Results_from_model!Q12 -> 0.157 | F12: =Results_from_model!R12 -> 0.199 | G12: =Results_from_model!S12 -> 0.081 | H12: =Results_from_model!T12 -> 0.282 | I12: =Results_from_model!U12 -> -0.054 | ... M12: =Results_from_model!Y12 -> 0.121
A13: 2Q4 | B13: =Results_from_model!N13 -> 0.396 | C13: =Results_from_model!O13 -> -0.11 | D13: =Results_from_model!P13 -> 0.197 | E13: =Results_from_model!Q13 -> 0.066 | F13: =Results_from_model!R13 -> 0.313 | G13: =Results_from_model!S13 -> 0.01 | H13: =Results_from_model!T13 -> 0.396 | I13: =Results_from_model!U13 -> -0.11 | ... M13: =Results_from_model!Y13 -> 0.044
A14: 3Q1 | B14: =Results_from_model!N14 -> 0.506 | C14: =Results_from_model!O14 -> -0.155 | D14: =Results_from_model!P14 -> 0.316 | E14: =Results_from_model!Q14 -> -0.014 | F14: =Results_from_model!R14 -> 0.425 | G14: =Results_from_model!S14 -> -0.051 | H14: =Results_from_model!T14 -> 0.506 | I14: =Results_from_model!U14 -> -0.155 | ... M14: =Results_from_model!Y14 -> -0.022 | R14: Infrastructure investment | S14: Human capital investment
A15: 3Q2 | B15: =Results_from_model!N15 -> 0.612 | C15: =Results_from_model!O15 -> -0.189 | D15: =Results_from_model!P15 -> 0.436 | E15: =Results_from_model!Q15 -> -0.083 | F15: =Results_from_model!R15 -> 0.534 | G15: =Results_from_model!S15 -> -0.101 | H15: =Results_from_model!T15 -> 0.612 | I15: =Results_from_model!U15 -> -0.189 | ... M15: =Results_from_model!Y15 -> -0.077 | P15: 2026 | Q15: 1Q4 | R15: =B9 -> -0.075 | S15: =C9 -> 0.182
A16: 3Q3 | B16: =Results_from_model!N16 -> 0.716 | C16: =Results_from_model!O16 -> -0.213 | D16: =Results_from_model!P16 -> 0.555 | E16: =Results_from_model!Q16 -> -0.142 | F16: =Results_from_model!R16 -> 0.642 | G16: =Results_from_model!S16 -> -0.141 | H16: =Results_from_model!T16 -> 0.716 | I16: =Results_from_model!U16 -> -0.213 | ... M16: =Results_from_model!Y16 -> -0.122 | P16: 2030 | Q16: 5Q4 | R16: =B25 -> 1.514 | S16: =C25 -> -0.072
A17: 3Q4 | B17: =Results_from_model!N17 -> 0.816 | C17: =Results_from_model!O17 -> -0.228 | D17: =Results_from_model!P17 -> 0.674 | E17: =Results_from_model!Q17 -> -0.19 | F17: =Results_from_model!R17 -> 0.748 | G17: =Results_from_model!S17 -> -0.172 | H17: =Results_from_model!T17 -> 0.816 | I17: =Results_from_model!U17 -> -0.228 | ... M17: =Results_from_model!Y17 -> -0.158 | P17: 2040 | Q17: 15Q4 | R17: =B65 -> 3.26 | S17: =C65 -> 3.107
A18: 4Q1 | B18: =Results_from_model!N18 -> 0.913 | C18: =Results_from_model!O18 -> -0.233 | D18: =Results_from_model!P18 -> 0.792 | E18: =Results_from_model!Q18 -> -0.228 | F18: =Results_from_model!R18 -> 0.852 | G18: =Results_from_model!S18 -> -0.192 | H18: =Results_from_model!T18 -> 0.913 | I18: =Results_from_model!U18 -> -0.233 | ... M18: =Results_from_model!Y18 -> -0.183 | P18: 2050 | Q18: 25Q4 | R18: =B105 -> 3.746 | S18: =C105 -> 5.464
A19: 4Q2 | B19: =Results_from_model!N19 -> 1.007 | C19: =Results_from_model!O19 -> -0.231 | D19: =Results_from_model!P19 -> 0.911 | E19: =Results_from_model!Q19 -> -0.257 | F19: =Results_from_model!R19 -> 0.954 | G19: =Results_from_model!S19 -> -0.205 | H19: =Results_from_model!T19 -> 1.007 | I19: =Results_from_model!U19 -> -0.231 | ... M19: =Results_from_model!Y19 -> -0.2
A20: 4Q3 | B20: =Results_from_model!N20 -> 1.098 | C20: =Results_from_model!O20 -> -0.221 | D20: =Results_from_model!P20 -> 1.029 | E20: =Results_from_model!Q20 -> -0.276 | F20: =Results_from_model!R20 -> 1.054 | G20: =Results_from_model!S20 -> -0.208 | H20: =Results_from_model!T20 -> 1.098 | I20: =Results_from_model!U20 -> -0.221 | ... M20: =Results_from_model!Y20 -> -0.208
A21: 4Q4 | B21: =Results_from_model!N21 -> 1.186 | C21: =Results_from_model!O21 -> -0.204 | D21: =Results_from_model!P21 -> 1.147 | E21: =Results_from_model!Q21 -> -0.286 | F21: =Results_from_model!R21 -> 1.152 | G21: =Results_from_model!S21 -> -0.204 | H21: =Results_from_model!T21 -> 1.186 | I21: =Results_from_model!U21 -> -0.204 | ... M21: =Results_from_model!Y21 -> -0.208
A22: 5Q1 | B22: =Results_from_model!N22 -> 1.272 | C22: =Results_from_model!O22 -> -0.18 | D22: =Results_from_model!P22 -> 1.265 | E22: =Results_from_model!Q22 -> -0.287 | F22: =Results_from_model!R22 -> 1.248 | G22: =Results_from_model!S22 -> -0.193 | H22: =Results_from_model!T22 -> 1.272 | I22: =Results_from_model!U22 -> -0.18 | ... M22: =Results_from_model!Y22 -> -0.2
A23: 5Q2 | B23: =Results_from_model!N23 -> 1.355 | C23: =Results_from_model!O23 -> -0.15 | D23: =Results_from_model!P23 -> 1.382 | E23: =Results_from_model!Q23 -> -0.28 | F23: =Results_from_model!R23 -> 1.343 | G23: =Results_from_model!S23 -> -0.174 | H23: =Results_from_model!T23 -> 1.355 | I23: =Results_from_model!U23 -> -0.15 | ... M23: =Results_from_model!Y23 -> -0.185
A24: 5Q3 | B24: =Results_from_model!N24 -> 1.436 | C24: =Results_from_model!O24 -> -0.114 | D24: =Results_from_model!P24 -> 1.499 | E24: =Results_from_model!Q24 -> -0.265 | F24: =Results_from_model!R24 -> 1.436 | G24: =Results_from_model!S24 -> -0.149 | H24: =Results_from_model!T24 -> 1.436 | I24: =Results_from_model!U24 -> -0.114 | ... M24: =Results_from_model!Y24 -> -0.163
A25: 5Q4 | B25: =Results_from_model!N25 -> 1.514 | C25: =Results_from_model!O25 -> -0.072 | D25: =Results_from_model!P25 -> 1.616 | E25: =Results_from_model!Q25 -> -0.242 | F25: =Results_from_model!R25 -> 1.528 | G25: =Results_from_model!S25 -> -0.117 | H25: =Results_from_model!T25 -> 1.514 | I25: =Results_from_model!U25 -> -0.072 | ... M25: =Results_from_model!Y25 -> -0.135
A26: 6Q1 | B26: =Results_from_model!N26 -> 1.589 | C26: =Results_from_model!O26 -> -0.026 | D26: =Results_from_model!P26 -> 1.733 | E26: =Results_from_model!Q26 -> -0.212 | F26: =Results_from_model!R26 -> 1.618 | G26: =Results_from_model!S26 -> -0.08 | H26: =Results_from_model!T26 -> 1.589 | I26: =Results_from_model!U26 -> -0.026 | ... M26: =Results_from_model!Y26 -> -0.1
A27: 6Q2 | B27: =Results_from_model!N27 -> 1.662 | C27: =Results_from_model!O27 -> 0.025 | D27: =Results_from_model!P27 -> 1.85 | E27: =Results_from_model!Q27 -> -0.175 | F27: =Results_from_model!R27 -> 1.706 | G27: =Results_from_model!S27 -> -0.036 | H27: =Results_from_model!T27 -> 1.662 | I27: =Results_from_model!U27 -> 0.025 | ... M27: =Results_from_model!Y27 -> -0.059
A28: 6Q3 | B28: =Results_from_model!N28 -> 1.733 | C28: =Results_from_model!O28 -> 0.08 | D28: =Results_from_model!P28 -> 1.966 | E28: =Results_from_model!Q28 -> -0.13 | F28: =Results_from_model!R28 -> 1.793 | G28: =Results_from_model!S28 -> 0.012 | H28: =Results_from_model!T28 -> 1.733 | I28: =Results_from_model!U28 -> 0.08 | ... M28: =Results_from_model!Y28 -> -0.012
A29: 6Q4 | B29: =Results_from_model!N29 -> 1.802 | C29: =Results_from_model!O29 -> 0.14 | D29: =Results_from_model!P29 -> 2.082 | E29: =Results_from_model!Q29 -> -0.079 | F29: =Results_from_model!R29 -> 1.878 | G29: =Results_from_model!S29 -> 0.065 | H29: =Results_from_model!T29 -> 1.802 | I29: =Results_from_model!U29 -> 0.14 | ... M29: =Results_from_model!Y29 -> 0.04
A30: 7Q1 | B30: =Results_from_model!N30 -> 1.869 | C30: =Results_from_model!O30 -> 0.202 | D30: =Results_from_model!P30 -> 2.197 | E30: =Results_from_model!Q30 -> -0.022 | F30: =Results_from_model!R30 -> 1.962 | G30: =Results_from_model!S30 -> 0.123 | H30: =Results_from_model!T30 -> 1.869 | I30: =Results_from_model!U30 -> 0.202 | ... M30: =Results_from_model!Y30 -> 0.097
... A43: 10Q2 | B43: =Results_from_model!N43 -> 2.569 | C43: =Results_from_model!O43 -> 1.224 | D43: =Results_from_model!P43 -> 3.7 | E43: =Results_from_model!Q43 -> 1.191 | F43: =Results_from_model!R43 -> 2.942 | G43: =Results_from_model!S43 -> 1.189 | H43: =Results_from_model!T43 -> 2.569 | I43: =Results_from_model!U43 -> 1.224 | ... M43: =Results_from_model!Y43 -> 1.182
A44: 10Q3 | B44: =Results_from_model!N44 -> 2.612 | C44: =Results_from_model!O44 -> 1.311 | D44: =Results_from_model!P44 -> 3.818 | E44: =Results_from_model!Q44 -> 1.314 | F44: =Results_from_model!R44 -> 3.01 | G44: =Results_from_model!S44 -> 1.288 | H44: =Results_from_model!T44 -> 2.612 | I44: =Results_from_model!U44 -> 1.311 | ... M44: =Results_from_model!Y44 -> 1.284 | R44: Infrastructure investment | S44: Human capital investment | AB44: Figure 6D
A45: 10Q4 | B45: =Results_from_model!N45 -> 2.654 | C45: =Results_from_model!O45 -> 1.399 | D45: =Results_from_model!P45 -> 3.936 | E45: =Results_from_model!Q45 -> 1.439 | F45: =Results_from_model!R45 -> 3.077 | G45: =Results_from_model!S45 -> 1.388 | H45: =Results_from_model!T45 -> 2.654 | I45: =Results_from_model!U45 -> 1.399 | ... M45: =Results_from_model!Y45 -> 1.389 | O45: 25Q4 | P45: 0.8 | Q45: Initial efficiency: 0.8 (Baseline) | R45: =VLOOKUP($O45,$A:$G,2,FALSE) -> 3.746 | S45: =VLOOKUP($O45,$A:$G,3,FALSE) -> 5.464
A46: 11Q1 | B46: =Results_from_model!N46 -> 2.694 | C46: =Results_from_model!O46 -> 1.487 | D46: =Results_from_model!P46 -> 4.055 | E46: =Results_from_model!Q46 -> 1.568 | F46: =Results_from_model!R46 -> 3.143 | G46: =Results_from_model!S46 -> 1.49 | H46: =Results_from_model!T46 -> 2.694 | I46: =Results_from_model!U46 -> 1.487 | ... M46: =Results_from_model!Y46 -> 1.496 | O46: 25Q4 | P46: 1 | Q46: Closing gap by 2050 | R46: =VLOOKUP($O46,$A:$G,6,FALSE) -> 6.147 | S46: =VLOOKUP($O46,$A:$G,7,FALSE) -> 7.872
A47: 11Q2 | B47: =Results_from_model!N47 -> 2.733 | C47: =Results_from_model!O47 -> 1.575 | D47: =Results_from_model!P47 -> 4.17 | E47: =Results_from_model!Q47 -> 1.702 | F47: =Results_from_model!R47 -> 3.209 | G47: =Results_from_model!S47 -> 1.593 | H47: =Results_from_model!T47 -> 2.733 | I47: =Results_from_model!U47 -> 1.575 | ... M47: =Results_from_model!Y47 -> 1.604 | O47: 25Q4 | P47: 1 | Q47: Closing gap by 2035 | R47: =VLOOKUP($O47,$A:$G,4,FALSE) -> 7.147 | S47: =VLOOKUP($O47,$A:$G,5,FALSE) -> 10.387
A48: 11Q3 | B48: =Results_from_model!N48 -> 2.771 | C48: =Results_from_model!O48 -> 1.664 | D48: =Results_from_model!P48 -> 4.282 | E48: =Results_from_model!Q48 -> 1.841 | F48: =Results_from_model!R48 -> 3.273 | G48: =Results_from_model!S48 -> 1.697 | H48: =Results_from_model!T48 -> 2.771 | I48: =Results_from_model!U48 -> 1.664 | ... M48: =Results_from_model!Y48 -> 1.714
A49: 11Q4 | B49: =Results_from_model!N49 -> 2.808 | C49: =Results_from_model!O49 -> 1.752 | D49: =Results_from_model!P49 -> 4.391 | E49: =Results_from_model!Q49 -> 1.985 | F49: =Results_from_model!R49 -> 3.336 | G49: =Results_from_model!S49 -> 1.802 | H49: =Results_from_model!T49 -> 2.808 | I49: =Results_from_model!U49 -> 1.752 | ... M49: =Results_from_model!Y49 -> 1.825
A50: 12Q1 | B50: =Results_from_model!N50 -> 2.843 | C50: =Results_from_model!O50 -> 1.84 | D50: =Results_from_model!P50 -> 4.496 | E50: =Results_from_model!Q50 -> 2.133 | F50: =Results_from_model!R50 -> 3.399 | G50: =Results_from_model!S50 -> 1.909 | H50: =Results_from_model!T50 -> 2.843 | I50: =Results_from_model!U50 -> 1.84 | ... M50: =Results_from_model!Y50 -> 1.938 | R50: Infrastructure investment | S50: Human capital investment
A51: 12Q2 | B51: =Results_from_model!N51 -> 2.877 | C51: =Results_from_model!O51 -> 1.928 | D51: =Results_from_model!P51 -> 4.598 | E51: =Results_from_model!Q51 -> 2.285 | F51: =Results_from_model!R51 -> 3.461 | G51: =Results_from_model!S51 -> 2.016 | H51: =Results_from_model!T51 -> 2.877 | I51: =Results_from_model!U51 -> 1.928 | ... M51: =Results_from_model!Y51 -> 2.052 | O51: 25Q4 | P51: 0.6 | Q51: Initial efficiency: 0.6 | R51: =VLOOKUP($O51,$A:$M,8,FALSE) -> 3.746 | S51: =VLOOKUP($O51,$A:$M,9,FALSE) -> 5.464
A52: 12Q3 | B52: =Results_from_model!N52 -> 2.911 | C52: =Results_from_model!O52 -> 2.016 | D52: =Results_from_model!P52 -> 4.696 | E52: =Results_from_model!Q52 -> 2.44 | F52: =Results_from_model!R52 -> 3.522 | G52: =Results_from_model!S52 -> 2.124 | H52: =Results_from_model!T52 -> 2.911 | I52: =Results_from_model!U52 -> 2.016 | ... M52: =Results_from_model!Y52 -> 2.167 | O52: 25Q4 | P52: 0.8 | Q52: Closing gap by 2050 | R52: =VLOOKUP($O52,$A:$M,12,FALSE) -> 6.876 | S52: =VLOOKUP($O52,$A:$M,13,FALSE) -> 8.653
A53: 12Q4 | B53: =Results_from_model!N53 -> 2.943 | C53: =Results_from_model!O53 -> 2.104 | D53: =Results_from_model!P53 -> 4.791 | E53: =Results_from_model!Q53 -> 2.599 | F53: =Results_from_model!R53 -> 3.583 | G53: =Results_from_model!S53 -> 2.233 | H53: =Results_from_model!T53 -> 2.943 | I53: =Results_from_model!U53 -> 2.104 | ... M53: =Results_from_model!Y53 -> 2.283 | O53: 25Q4 | P53: 0.8 | Q53: Closing gap by 2035 | R53: =VLOOKUP($O53,$A:$M,10,FALSE) -> 8.148 | S53: =VLOOKUP($O53,$A:$M,11,FALSE) -> 11.916
A54: 13Q1 | B54: =Results_from_model!N54 -> 2.974 | C54: =Results_from_model!O54 -> 2.191 | D54: =Results_from_model!P54 -> 4.884 | E54: =Results_from_model!Q54 -> 2.76 | F54: =Results_from_model!R54 -> 3.643 | G54: =Results_from_model!S54 -> 2.343 | H54: =Results_from_model!T54 -> 2.974 | I54: =Results_from_model!U54 -> 2.191 | ... M54: =Results_from_model!Y54 -> 2.4
A55: 13Q2 | B55: =Results_from_model!N55 -> 3.005 | C55: =Results_from_model!O55 -> 2.277 | D55: =Results_from_model!P55 -> 4.973 | E55: =Results_from_model!Q55 -> 2.923 | F55: =Results_from_model!R55 -> 3.702 | G55: =Results_from_model!S55 -> 2.453 | H55: =Results_from_model!T55 -> 3.005 | I55: =Results_from_model!U55 -> 2.277 | ... M55: =Results_from_model!Y55 -> 2.518
A56: 13Q3 | B56: =Results_from_model!N56 -> 3.034 | C56: =Results_from_model!O56 -> 2.363 | D56: =Results_from_model!P56 -> 5.059 | E56: =Results_from_model!Q56 -> 3.089 | F56: =Results_from_model!R56 -> 3.76 | G56: =Results_from_model!S56 -> 2.563 | H56: =Results_from_model!T56 -> 3.034 | I56: =Results_from_model!U56 -> 2.363 | ... M56: =Results_from_model!Y56 -> 2.637
...

Sheet Figure_6A_6C_6E_6F
A1: 1 | B1: 2 | C1: 3 | D1: 4 | E1: 5 | F1: 6 | G1: 7 | H1: 8 | I1: 9
A2: AE | B2: Variables -> | C2: Model_HumanCapital_epsi_ig___yd | D2: Model_HumanCapital_epsi_cge___yd | E2: Model_HumanCapital_epsi_cgrd___yd | F2: Model_HumanCapital_epsi_igeff10y___yd | G2: Model_HumanCapital_epsi_cgeeff10y___yd | H2: Model_HumanCapital_epsi_cgrd_eff___yd | I2: Model_HumanCapital_epsi_cgeCgrd___yd | J2: Model_HumanCapital_epsi_cgeCgrd_advt___yd | K2: Model_HumanCapital_epsi_cgeCgrd_limt___yd
B3: Comments ->
B4: Class[Size] -> | C4: Series[201-by-1] | D4: Series[201-by-1] | E4: Series[201-by-1] | F4: Series[201-by-1] | G4: Series[201-by-1] | I4: Series[2002-by-1]
V8: Infrastructure investment | W8: Human capital investment | X8: R&D spending
A9: 2026 | C9: =Results_from_model!C9 -> -0.132 | D9: =Results_from_model!D9 -> -0.175 | E9: =Results_from_model!E9 -> -0.369 | F9: =Results_from_model!F9 -> -0.177 | G9: =Results_from_model!G9 -> -0.189 | H9: =Results_from_model!H9 -> -0.427 | I9: =Results_from_model!I9 -> -0.315 | J9: =Results_from_model!J9 -> -0.782 | K9: =Results_from_model!K9 -> 0.147 | T9: 2026 | U9: 1Q4 | V9: =C9 -> -0.132 | W9: =D9 -> -0.175 | X9: =E9 -> -0.369 | Y9: =I9 -> -0.315
A10: =A9+0.25 -> 2026.25 | C10: =Results_from_model!C10 -> -0.075 | D10: =Results_from_model!D10 -> -0.201 | E10: =Results_from_model!E10 -> -0.376 | F10: =Results_from_model!F10 -> -0.122 | G10: =Results_from_model!G10 -> -0.22 | H10: =Results_from_model!H10 -> -0.44 | I10: =Results_from_model!I10 -> -0.332 | J10: =Results_from_model!J10 -> -0.852 | K10: =Results_from_model!K10 -> 0.185 | T10: 2030 | U10: 5Q4 | V10: =C25 -> 0.619 | W10: =D25 -> -0.214 | X10: =E25 -> 0.473 | Y10: =I25 -> 0.195
A11: =A10+0.25 -> 2026.5 | C11: =Results_from_model!C11 -> -0.02 | D11: =Results_from_model!D11 -> -0.224 | E11: =Results_from_model!E11 -> -0.364 | F11: =Results_from_model!F11 -> -0.067 | G11: =Results_from_model!G11 -> -0.248 | H11: =Results_from_model!H11 -> -0.435 | I11: =Results_from_model!I11 -> -0.336 | J11: =Results_from_model!J11 -> -0.907 | K11: =Results_from_model!K11 -> 0.237 | T11: 2040 | U11: 15Q4 | V11: =C65 -> 1.658 | W11: =D65 -> 1.435 | X11: =E65 -> 2.365 | Y11: =I65 -> 2.202
A12: =A11+0.25 -> 2026.75 | C12: =Results_from_model!C12 -> 0.034 | D12: =Results_from_model!D12 -> -0.243 | E12: =Results_from_model!E12 -> -0.337 | F12: =Results_from_model!F12 -> -0.014 | G12: =Results_from_model!G12 -> -0.273 | H12: =Results_from_model!H12 -> -0.415 | I12: =Results_from_model!I12 -> -0.328 | J12: =Results_from_model!J12 -> -0.948 | K12: =Results_from_model!K12 -> 0.297 | T12: 2050 | U12: 25Q4 | V12: =C105 -> 2.155 | W12: =D105 -> 3.285 | X12: =E105 -> 3.211 | Y12: =I105 -> 3.699
A13: =A12+0.25 -> 2027 | C13: =Results_from_model!C13 -> 0.087 | D13: =Results_from_model!D13 -> -0.259 | E13: =Results_from_model!E13 -> -0.298 | F13: =Results_from_model!F13 -> 0.039 | G13: =Results_from_model!G13 -> -0.295 | H13: =Results_from_model!H13 -> -0.382 | I13: =Results_from_model!I13 -> -0.312 | J13: =Results_from_model!J13 -> -0.975 | K13: =Results_from_model!K13 -> 0.364
A14: =A13+0.25 -> 2027.25 | C14: =Results_from_model!C14 -> 0.138 | D14: =Results_from_model!D14 -> -0.272 | E14: =Results_from_model!E14 -> -0.25 | F14: =Results_from_model!F14 -> 0.09 | G14: =Results_from_model!G14 -> -0.313 | H14: =Results_from_model!H14 -> -0.34 | I14: =Results_from_model!I14 -> -0.287 | J14: =Results_from_model!J14 -> -0.992 | K14: =Results_from_model!K14 -> 0.435
A15: =A14+0.25 -> 2027.5 | C15: =Results_from_model!C15 -> 0.188 | D15: =Results_from_model!D15 -> -0.281 | E15: =Results_from_model!E15 -> -0.196 | F15: =Results_from_model!F15 -> 0.141 | G15: =Results_from_model!G15 -> -0.327 | H15: =Results_from_model!H15 -> -0.29 | I15: =Results_from_model!I15 -> -0.257 | J15: =Results_from_model!J15 -> -1 | K15: =Results_from_model!K15 -> 0.509
A16: =A15+0.25 -> 2027.75 | C16: =Results_from_model!C16 -> 0.236 | D16: =Results_from_model!D16 -> -0.287 | E16: =Results_from_model!E16 -> -0.136 | F16: =Results_from_model!F16 -> 0.19 | G16: =Results_from_model!G16 -> -0.338 | H16: =Results_from_model!H16 -> -0.234 | I16: =Results_from_model!I16 -> -0.222 | J16: =Results_from_model!J16 -> -0.999 | K16: =Results_from_model!K16 -> 0.584
A17: =A16+0.25 -> 2028 | C17: =Results_from_model!C17 -> 0.283 | D17: =Results_from_model!D17 -> -0.289 | E17: =Results_from_model!E17 -> -0.072 | F17: =Results_from_model!F17 -> 0.239 | G17: =Results_from_model!G17 -> -0.346 | H17: =Results_from_model!H17 -> -0.174 | I17: =Results_from_model!I17 -> -0.184 | J17: =Results_from_model!J17 -> -0.991 | K17: =Results_from_model!K17 -> 0.66
A18: =A17+0.25 -> 2028.25 | C18: =Results_from_model!C18 -> 0.329 | D18: =Results_from_model!D18 -> -0.289 | E18: =Results_from_model!E18 -> -0.006 | F18: =Results_from_model!F18 -> 0.286 | G18: =Results_from_model!G18 -> -0.35 | H18: =Results_from_model!H18 -> -0.111 | I18: =Results_from_model!I18 -> -0.142 | J18: =Results_from_model!J18 -> -0.976 | K18: =Results_from_model!K18 -> 0.736
A19: =A18+0.25 -> 2028.5 | C19: =Results_from_model!C19 -> 0.374 | D19: =Results_from_model!D19 -> -0.286 | E19: =Results_from_model!E19 -> 0.061 | F19: =Results_from_model!F19 -> 0.333 | G19: =Results_from_model!G19 -> -0.352 | H19: =Results_from_model!H19 -> -0.045 | I19: =Results_from_model!I19 -> -0.098 | J19: =Results_from_model!J19 -> -0.956 | K19: =Results_from_model!K19 -> 0.811
A20: =A19+0.25 -> 2028.75 | C20: =Results_from_model!C20 -> 0.417 | D20: =Results_from_model!D20 -> -0.28 | E20: =Results_from_model!E20 -> 0.13 | F20: =Results_from_model!F20 -> 0.379 | G20: =Results_from_model!G20 -> -0.351 | H20: =Results_from_model!H20 -> 0.022 | I20: =Results_from_model!I20 -> -0.052 | J20: =Results_from_model!J20 -> -0.931 | K20: =Results_from_model!K20 -> 0.886
A21: =A20+0.25 -> 2029 | C21: =Results_from_model!C21 -> 0.459 | D21: =Results_from_model!D21 -> -0.272 | E21: =Results_from_model!E21 -> 0.199 | F21: =Results_from_model!F21 -> 0.424 | G21: =Results_from_model!G21 -> -0.346 | H21: =Results_from_model!H21 -> 0.091 | I21: =Results_from_model!I21 -> -0.005 | J21: =Results_from_model!J21 -> -0.901 | K21: =Results_from_model!K21 -> 0.958
A22: =A21+0.25 -> 2029.25 | C22: =Results_from_model!C22 -> 0.501 | D22: =Results_from_model!D22 -> -0.261 | E22: =Results_from_model!E22 -> 0.268 | F22: =Results_from_model!F22 -> 0.469 | G22: =Results_from_model!G22 -> -0.339 | H22: =Results_from_model!H22 -> 0.16 | I22: =Results_from_model!I22 -> 0.044 | J22: =Results_from_model!J22 -> -0.866 | K22: =Results_from_model!K22 -> 1.029
A23: =A22+0.25 -> 2029.5 | C23: =Results_from_model!C23 -> 0.541 | D23: =Results_from_model!D23 -> -0.247 | E23: =Results_from_model!E23 -> 0.337 | F23: =Results_from_model!F23 -> 0.513 | G23: =Results_from_model!G23 -> -0.33 | H23: =Results_from_model!H23 -> 0.23 | I23: =Results_from_model!I23 -> 0.094 | J23: =Results_from_model!J23 -> -0.826 | K23: =Results_from_model!K23 -> 1.097
A24: =A23+0.25 -> 2029.75 | C24: =Results_from_model!C24 -> 0.58 | D24: =Results_from_model!D24 -> -0.232 | E24: =Results_from_model!E24 -> 0.405 | F24: =Results_from_model!F24 -> 0.556 | G24: =Results_from_model!G24 -> -0.318 | H24: =Results_from_model!H24 -> 0.301 | I24: =Results_from_model!I24 -> 0.144 | J24: =Results_from_model!J24 -> -0.783 | K24: =Results_from_model!K24 -> 1.164
... A34: =A33+0.25 -> 2032.25 | C34: =Results_from_model!C34 -> 0.928 | D34: =Results_from_model!D34 -> 0.029 | E34: =Results_from_model!E34 -> 1.036 | F34: =Results_from_model!F34 -> 0.96 | G34: =Results_from_model!G34 -> -0.07 | H34: =Results_from_model!H34 -> 0.994 | I34: =Results_from_model!I34 -> 0.666 | J34: =Results_from_model!J34 -> -0.163 | K34: =Results_from_model!K34 -> 1.675
A35: =A34+0.25 -> 2032.5 | C35: =Results_from_model!C35 -> 0.959 | D35: =Results_from_model!D35 -> 0.063 | E35: =Results_from_model!E35 -> 1.093 | F35: =Results_from_model!F35 -> 0.998 | G35: =Results_from_model!G35 -> -0.034 | H35: =Results_from_model!H35 -> 1.061 | I35: =Results_from_model!I35 -> 0.719 | J35: =Results_from_model!J35 -> -0.084 | K35: =Results_from_model!K35 -> 1.708 | AD35: Figure 6C
A36: =A35+0.25 -> 2032.75 | C36: =Results_from_model!C36 -> 0.99 | D36: =Results_from_model!D36 -> 0.099 | E36: =Results_from_model!E36 -> 1.149 | F36: =Results_from_model!F36 -> 1.035 | G36: =Results_from_model!G36 -> 0.003 | H36: =Results_from_model!H36 -> 1.127 | I36: =Results_from_model!I36 -> 0.771 | J36: =Results_from_model!J36 -> -0.001 | K36: =Results_from_model!K36 -> 1.737
A37: =A36+0.25 -> 2033 | C37: =Results_from_model!C37 -> 1.019 | D37: =Results_from_model!D37 -> 0.136 | E37: =Results_from_model!E37 -> 1.203 | F37: =Results_from_model!F37 -> 1.073 | G37: =Results_from_model!G37 -> 0.042 | H37: =Results_from_model!H37 -> 1.194 | I37: =Results_from_model!I37 -> 0.824 | J37: =Results_from_model!J37 -> 0.085 | K37: =Results_from_model!K37 -> 1.762
A38: =A37+0.25 -> 2033.25 | C38: =Results_from_model!C38 -> 1.048 | D38: =Results_from_model!D38 -> 0.174 | E38: =Results_from_model!E38 -> 1.257 | F38: =Results_from_model!F38 -> 1.11 | G38: =Results_from_model!G38 -> 0.083 | H38: =Results_from_model!H38 -> 1.26 | I38: =Results_from_model!I38 -> 0.876 | J38: =Results_from_model!J38 -> 0.175 | K38: =Results_from_model!K38 -> 1.781
A39: =A38+0.25 -> 2033.5 | C39: =Results_from_model!C39 -> 1.077 | D39: =Results_from_model!D39 -> 0.213 | E39: =Results_from_model!E39 -> 1.31 | F39: =Results_from_model!F39 -> 1.146 | G39: =Results_from_model!G39 -> 0.125 | H39: =Results_from_model!H39 -> 1.325 | I39: =Results_from_model!I39 -> 0.928 | J39: =Results_from_model!J39 -> 0.268 | K39: =Results_from_model!K39 -> 1.797
A40: =A39+0.25 -> 2033.75 | C40: =Results_from_model!C40 -> 1.105 | D40: =Results_from_model!D40 -> 0.253 | E40: =Results_from_model!E40 -> 1.361 | F40: =Results_from_model!F40 -> 1.183 | G40: =Results_from_model!G40 -> 0.169 | H40: =Results_from_model!H40 -> 1.39 | I40: =Results_from_model!I40 -> 0.98 | J40: =Results_from_model!J40 -> 0.366 | K40: =Results_from_model!K40 -> 1.806
A41: =A40+0.25 -> 2034 | C41: =Results_from_model!C41 -> 1.132 | D41: =Results_from_model!D41 -> 0.295 | E41: =Results_from_model!E41 -> 1.412 | F41: =Results_from_model!F41 -> 1.219 | G41: =Results_from_model!G41 -> 0.214 | H41: =Results_from_model!H41 -> 1.455 | I41: =Results_from_model!I41 -> 1.032 | J41: =Results_from_model!J41 -> 0.467 | K41: =Results_from_model!K41 -> 1.811
A42: =A41+0.25 -> 2034.25 | C42: =Results_from_model!C42 -> 1.159 | D42: =Results_from_model!D42 -> 0.336 | E42: =Results_from_model!E42 -> 1.461 | F42: =Results_from_model!F42 -> 1.255 | G42: =Results_from_model!G42 -> 0.261 | H42: =Results_from_model!H42 -> 1.52 | I42: =Results_from_model!I42 -> 1.084 | J42: =Results_from_model!J42 -> 0.574 | K42: =Results_from_model!K42 -> 1.809
A43: =A42+0.25 -> 2034.5 | C43: =Results_from_model!C43 -> 1.186 | D43: =Results_from_model!D43 -> 0.379 | E43: =Results_from_model!E43 -> 1.51 | F43: =Results_from_model!F43 -> 1.291 | G43: =Results_from_model!G43 -> 0.308 | H43: =Results_from_model!H43 -> 1.584 | I43: =Results_from_model!I43 -> 1.135 | J43: =Results_from_model!J43 -> 0.686 | K43: =Results_from_model!K43 -> 1.799 | T43: Infrastructure investment | U43: Human capital investment | V43: R&D spending
A44: =A43+0.25 -> 2034.75 | C44: =Results_from_model!C44 -> 1.211 | D44: =Results_from_model!D44 -> 0.423 | E44: =Results_from_model!E44 -> 1.558 | F44: =Results_from_model!F44 -> 1.326 | G44: =Results_from_model!G44 -> 0.358 | H44: =Results_from_model!H44 -> 1.648 | I44: =Results_from_model!I44 -> 1.186 | J44: =Results_from_model!J44 -> 0.803 | K44: =Results_from_model!K44 -> 1.784 | T44: =F105-C105 -> 0.475 | U44: =G105-D105 -> 0.856 | V44: =H105-E105 -> 0.971
A45: =A44+0.25 -> 2035 | C45: =Results_from_model!C45 -> 1.237 | D45: =Results_from_model!D45 -> 0.467 | E45: =Results_from_model!E45 -> 1.604 | F45: =Results_from_model!F45 -> 1.361 | G45: =Results_from_model!G45 -> 0.408 | H45: =Results_from_model!H45 -> 1.712 | I45: =Results_from_model!I45 -> 1.238 | J45: =Results_from_model!J45 -> 0.926 | K45: =Results_from_model!K45 -> 1.761
A46: =A45+0.25 -> 2035.25 | C46: =Results_from_model!C46 -> 1.262 | D46: =Results_from_model!D46 -> 0.512 | E46: =Results_from_model!E46 -> 1.65 | F46: =Results_from_model!F46 -> 1.396 | G46: =Results_from_model!G46 -> 0.46 | H46: =Results_from_model!H46 -> 1.775 | I46: =Results_from_model!I46 -> 1.288 | J46: =Results_from_model!J46 -> 1.056 | K46: =Results_from_model!K46 -> 1.732
A47: =A46+0.25 -> 2035.5 | C47: =Results_from_model!C47 -> 1.286 | D47: =Results_from_model!D47 -> 0.557 | E47: =Results_from_model!E47 -> 1.695 | F47: =Results_from_model!F47 -> 1.431 | G47: =Results_from_model!G47 -> 0.513 | H47: =Results_from_model!H47 -> 1.839 | I47: =Results_from_model!I47 -> 1.339 | J47: =Results_from_model!J47 -> 1.184 | K47: =Results_from_model!K47 -> 1.703
A48: =A47+0.25 -> 2035.75 | C48: =Results_from_model!C48 -> 1.31 | D48: =Results_from_model!D48 -> 0.603 | E48: =Results_from_model!E48 -> 1.739 | F48: =Results_from_model!F48 -> 1.464 | G48: =Results_from_model!G48 -> 0.567 | H48: =Results_from_model!H48 -> 1.902 | I48: =Results_from_model!I48 -> 1.39 | J48: =Results_from_model!J48 -> 1.311 | K48: =Results_from_model!K48 -> 1.674
A49: =A48+0.25 -> 2036 | C49: =Results_from_model!C49 -> 1.334 | D49: =Results_from_model!D49 -> 0.65 | E49: =Results_from_model!E49 -> 1.782 | F49: =Results_from_model!F49 -> 1.497 | G49: =Results_from_model!G49 -> 0.623 | H49: =Results_from_model!H49 -> 1.965 | I49: =Results_from_model!I49 -> 1.44 | J49: =Results_from_model!J49 -> 1.435 | K49: =Results_from_model!K49 -> 1.647
A50: =A49+0.25 -> 2036.25 | C50: =Results_from_model!C50 -> 1.357 | D50: =Results_from_model!D50 -> 0.697 | E50: =Results_from_model!E50 -> 1.824 | F50: =Results_from_model!F50 -> 1.53 | G50: =Results_from_model!G50 -> 0.679 | H50: =Results_from_model!H50 -> 2.028 | I50: =Results_from_model!I50 -> 1.49 | J50: =Results_from_model!J50 -> 1.557 | K50: =Results_from_model!K50 -> 1.621
A51: =A50+0.25 -> 2036.5 | C51: =Results_from_model!C51 -> 1.38 | D51: =Results_from_model!D51 -> 0.744 | E51: =Results_from_model!E51 -> 1.865 | F51: =Results_from_model!F51 -> 1.562 | G51: =Results_from_model!G51 -> 0.737 | H51: =Results_from_model!H51 -> 2.09 | I51: =Results_from_model!I51 -> 1.539 | J51: =Results_from_model!J51 -> 1.676 | K51: =Results_from_model!K51 -> 1.596
A52: =A51+0.25 -> 2036.75 | C52: =Results_from_model!C52 -> 1.402 | D52: =Results_from_model!D52 -> 0.792 | E52: =Results_from_model!E52 -> 1.906 | F52: =Results_from_model!F52 -> 1.593 | G52: =Results_from_model!G52 -> 0.795 | H52: =Results_from_model!H52 -> 2.151 | I52: =Results_from_model!I52 -> 1.589 | J52: =Results_from_model!J52 -> 1.793 | K52: =Results_from_model!K52 -> 1.572
...

Sheet Not_used_Results_from_model_OLD
A1: 1 | B1: 2 | C1: 3 | D1: 4 | E1: 5 | F1: 6 | G1: 7 | H1: 8 | I1: 9 | N1: 2 | O1: 3 | P1: 4 | Q1: 5 | R1: 6 | S1: 7 | T1: 8 | U1: 9 | V1: 10 | W1: 11 | X1: 12 | Y1: 13
A2: AE | B2: Variables -> | C2: Model_HumanCapital_epsi_ig___yd | D2: Model_HumanCapital_epsi_cge___yd | E2: Model_HumanCapital_epsi_cgrd___yd | F2: Model_HumanCapital_epsi_igeff10y___yd | G2: Model_HumanCapital_epsi_cgeeff10y___yd | H2: Model_HumanCapital_epsi_cgrd_eff__yd | I2: Model_HumanCapital_epsi_cgeCgrd__yd | J2: Model_HumanCapital_epsi_cgeCgrd_advt__yd | K2: Model_HumanCapital_epsi_cgeCgrd_limt__yd | M2: EMDE | N2: EM_Model_HumanCapital_epsiig___yd | O2: EM_Model_HumanCapital_epsicge___yd | P2: EM_Model_HumanCapital_epsiigeff10y___yd | Q2: EM_Model_HumanCapital_epsicgeeff10y___yd | R2: EM_Model_HumanCapital_epsiigeff25y___yd | S2: EM_Model_HumanCapital_epsicgeeff25y___yd | T2: EM_Model_HumanCapital_epsiiglow__yd | U2: EM_Model_HumanCapital_epsicgelow__yd | V2: EM_Model_HumanCapital_epsiigeff10ylow__yd | W2: EM_Model_HumanCapital_epsicgeeff10ylow__yd | X2: EM_Model_HumanCapital_epsiigeff25ylow__yd | Y2: EM_Model_HumanCapital_epsicgeeff25ylow__yd
B3: Comments ->
B4: Class[Size] -> | C4: Series[201-by-1] | D4: Series[201-by-1] | E4: Series[201-by-1] | F4: Series[201-by-1] | G4: Series[201-by-1] | I4: Series[2002-by-1] | N4: Series[201-by-1] | O4: Series[201-by-1] | P4: Series[201-by-1] | Q4: Series[201-by-1] | R4: Series[201-by-1] | S4: Series[201-by-1]
A9: 2026 | C9: =HLOOKUP(C2,#REF!,6,FALSE) -> #REF! | D9: -0.175 | E9: -0.369 | F9: -0.177 | G9: -0.189 | H9: -0.42654873 | I9: -0.315 | J9: -0.78191876 | K9: 0.14670952 | N9: -0.075 | O9: 0.182 | P9: -0.272 | Q9: 0.492 | R9: -0.15 | S9: 0.362
A10: =A9+0.25 -> 2026.25 | C10: -0.075 | D10: -0.201 | E10: -0.376 | F10: -0.122 | G10: -0.22 | H10: -0.44013753 | I10: -0.332 | J10: -0.85200773 | K10: 0.18475969 | N10: 0.046 | O10: 0.093 | P10: -0.158 | Q10: 0.372 | R10: -0.034 | S10: 0.259
A11: =A10+0.25 -> 2026.5 | C11: -0.02 | D11: -0.224 | E11: -0.364 | F11: -0.067 | G11: -0.248 | H11: -0.43523672 | I11: -0.336 | J11: -0.90709675 | K11: 0.23651489 | N11: 0.165 | O11: 0.014 | P11: -0.04 | Q11: 0.26 | R11: 0.083 | S11: 0.165
A12: =A11+0.25 -> 2026.75 | C12: 0.034 | D12: -0.243 | E12: -0.337 | F12: -0.014 | G12: -0.273 | H12: -0.41487159 | I12: -0.328 | J12: -0.94757748 | K12: 0.29705413 | N12: 0.282 | O12: -0.054 | P12: 0.078 | Q12: 0.157 | R12: 0.199 | S12: 0.081
A13: =A12+0.25 -> 2027 | C13: 0.087 | D13: -0.259 | E13: -0.298 | F13: 0.039 | G13: -0.295 | H13: -0.38216391 | I13: -0.312 | J13: -0.9750975 | K13: 0.36350619 | N13: 0.396 | O13: -0.11 | P13: 0.197 | Q13: 0.066 | R13: 0.313 | S13: 0.01
A14: =A13+0.25 -> 2027.25 | C14: 0.138 | D14: -0.272 | E14: -0.25 | F14: 0.09 | G14: -0.313 | H14: -0.33979807 | I14: -0.287 | J14: -0.99201143 | K14: 0.43460707 | N14: 0.506 | O14: -0.155 | P14: 0.316 | Q14: -0.014 | R14: 0.425 | S14: -0.051
A15: =A14+0.25 -> 2027.5 | C15: 0.188 | D15: -0.281 | E15: -0.196 | F15: 0.141 | G15: -0.327 | H15: -0.28995539 | I15: -0.257 | J15: -0.99986603 | K15: 0.50888041 | N15: 0.612 | O15: -0.189 | P15: 0.436 | Q15: -0.083 | R15: 0.534 | S15: -0.101
A16: =A15+0.25 -> 2027.75 | C16: 0.236 | D16: -0.287 | E16: -0.136 | F16: 0.19 | G16: -0.338 | H16: -0.23437239 | I16: -0.222 | J16: -0.99918492 | K16: 0.58433302 | N16: 0.716 | O16: -0.213 | P16: 0.555 | Q16: -0.142 | R16: 0.642 | S16: -0.141
A17: =A16+0.25 -> 2028 | C17: 0.283 | D17: -0.289 | E17: -0.072 | F17: 0.239 | G17: -0.346 | H17: -0.17442063 | I17: -0.184 | J17: -0.99084891 | K17: 0.6599488 | N17: 0.816 | O17: -0.228 | P17: 0.674 | Q17: -0.19 | R17: 0.748 | S17: -0.172
A18: =A17+0.25 -> 2028.25 | C18: 0.329 | D18: -0.289 | E18: -0.006 | F18: 0.286 | G18: -0.35 | H18: -0.11117975 | I18: -0.142 | J18: -0.97633782 | K18: 0.73579093 | N18: 0.913 | O18: -0.233 | P18: 0.792 | Q18: -0.228 | R18: 0.852 | S18: -0.192
A19: =A18+0.25 -> 2028.5 | C19: 0.374 | D19: -0.286 | E19: 0.061 | F19: 0.333 | G19: -0.352 | H19: -0.045498186 | I19: -0.098 | J19: -0.95640724 | K19: 0.81138165 | N19: 1.007 | O19: -0.231 | P19: 0.911 | Q19: -0.257 | R19: 0.954 | S19: -0.205
A20: =A19+0.25 -> 2028.75 | C20: 0.417 | D20: -0.28 | E20: 0.13 | F20: 0.379 | G20: -0.351 | H20: 0.021958332 | I20: -0.052 | J20: -0.93093781 | K20: 0.88554596 | N20: 1.098 | O20: -0.221 | P20: 1.029 | Q20: -0.276 | R20: 1.054 | S20: -0.208
A21: =A20+0.25 -> 2029 | C21: 0.459 | D21: -0.272 | E21: 0.199 | F21: 0.424 | G21: -0.346 | H21: 0.090668181 | I21: -0.005 | J21: -0.90087384 | K21: 0.95848518 | N21: 1.186 | O21: -0.204 | P21: 1.147 | Q21: -0.286 | R21: 1.152 | S21: -0.204
... A105: =A104+0.25 -> 2050 | C105: 2.155 | D105: 3.285 | E105: 3.211 | F105: 2.63 | G105: 4.141 | H105: 4.1821142 | I105: 3.699 | J105: 5.6944956 | K105: 1.2409603 | N105: 3.746 | O105: 5.464 | P105: 7.147 | Q105: 10.387 | R105: 6.147 | S105: 7.872
C108: =C105-Results_from_model!C105 -> 0 | D108: =D105-Results_from_model!D105 -> 0 | E108: =E105-Results_from_model!E105 -> 0 | F108: =F105-Results_from_model!F105 -> 0 | G108: =G105-Results_from_model!G105 -> 0 | H108: =H105-Results_from_model!H105 -> 0.00011422492 | I108: =I105-Results_from_model!I105 -> 0 | J108: =J105-Results_from_model!J105 -> 0.00049556081 | ... S108: =S105-Results_from_model!S105 -> 0

Sheet Results_from_model
A1: 1 | B1: 2 | C1: 3 | D1: 4 | E1: 5 | F1: 6 | G1: 7 | H1: 8 | I1: 9 | N1: 2 | O1: 3 | P1: 4 | Q1: 5 | R1: 6 | S1: 7 | T1: 8 | U1: 9 | V1: 10 | W1: 11 | X1: 12 | Y1: 13
A2: AE | B2: Variables -> | C2: Model_HumanCapital_epsi_ig___yd | D2: Model_HumanCapital_epsi_cge___yd | E2: Model_HumanCapital_epsi_cgrd___yd | F2: Model_HumanCapital_epsi_igeff10y___yd | G2: Model_HumanCapital_epsi_cgeeff10y___yd | H2: Model_HumanCapital_epsi_cgrd_eff___yd | I2: Model_HumanCapital_epsi_cgeCgrd___yd | J2: Model_HumanCapital_epsi_cgeCgrd_advt___yd | K2: Model_HumanCapital_epsi_cgeCgrd_limt___yd | M2: EMDE | N2: EM_Model_HumanCapital_epsiig___yd | O2: EM_Model_HumanCapital_epsicge___yd | P2: EM_Model_HumanCapital_epsiigeff10y___yd | Q2: EM_Model_HumanCapital_epsicgeeff10y___yd | R2: EM_Model_HumanCapital_epsiigeff25y___yd | S2: EM_Model_HumanCapital_epsicgeeff25y___yd | T2: EM_Model_HumanCapital_epsiiglow___yd | U2: EM_Model_HumanCapital_epsicgelow___yd | V2: EM_Model_HumanCapital_epsiigeff10ylow___yd | W2: EM_Model_HumanCapital_epsicgeeff10ylow___yd | X2: EM_Model_HumanCapital_epsiigeff25ylow___yd | Y2: EM_Model_HumanCapital_epsicgeeff25ylow___yd
B3: Comments ->
A9: 2026 | C9: =HLOOKUP(C$2,Models_Results!$B:$AP,$AC9,FALSE) -> -0.132 | D9: =HLOOKUP(D$2,Models_Results!$B:$AP,$AC9,FALSE) -> -0.175 | E9: =HLOOKUP(E$2,Models_Results!$B:$AP,$AC9,FALSE) -> -0.369 | F9: =HLOOKUP(F$2,Models_Results!$B:$AP,$AC9,FALSE) -> -0.177 | G9: =HLOOKUP(G$2,Models_Results!$B:$AP,$AC9,FALSE) -> -0.189 | H9: =HLOOKUP(H$2,Models_Results!$B:$AP,$AC9,FALSE) -> -0.427 | I9: =HLOOKUP(I$2,Models_Results!$B:$AP,$AC9,FALSE) -> -0.315 | J9: =HLOOKUP(J$2,Models_Results!$B:$AP,$AC9,FALSE) -> -0.782 | K9: =HLOOKUP(K$2,Models_Results!$B:$AP,$AC9,FALSE) -> 0.147 | N9: =HLOOKUP(N$2,Models_Results!$B:$AP,$AC9,FALSE) -> -0.075 | O9: =HLOOKUP(O$2,Models_Results!$B:$AP,$AC9,FALSE) -> 0.182 | P9: =HLOOKUP(P$2,Models_Results!$B:$AP,$AC9,FALSE) -> -0.272 | Q9: =HLOOKUP(Q$2,Models_Results!$B:$AP,$AC9,FALSE) -> 0.492 | R9: =HLOOKUP(R$2,Models_Results!$B:$AP,$AC9,FALSE) -> -0.15 | S9: =HLOOKUP(S$2,Models_Results!$B:$AP,$AC9,FALSE) -> 0.362 | T9: =HLOOKUP(T$2,Models_Results!$B:$AP,$AC9,FALSE) -> -0.075 | U9: =HLOOKUP(U$2,Models_Results!$B:$AP,$AC9,FALSE) -> 0.182 | ... Y9: =HLOOKUP(Y$2,Models_Results!$B:$AP,$AC9,FALSE) -> 0.415 | AC9: 6
A10: =A9+0.25 -> 2026.25 | C10: =HLOOKUP(C$2,Models_Results!$B:$AP,$AC10,FALSE) -> -0.075 | D10: =HLOOKUP(D$2,Models_Results!$B:$AP,$AC10,FALSE) -> -0.201 | E10: =HLOOKUP(E$2,Models_Results!$B:$AP,$AC10,FALSE) -> -0.376 | F10: =HLOOKUP(F$2,Models_Results!$B:$AP,$AC10,FALSE) -> -0.122 | G10: =HLOOKUP(G$2,Models_Results!$B:$AP,$AC10,FALSE) -> -0.22 | H10: =HLOOKUP(H$2,Models_Results!$B:$AP,$AC10,FALSE) -> -0.44 | I10: =HLOOKUP(I$2,Models_Results!$B:$AP,$AC10,FALSE) -> -0.332 | J10: =HLOOKUP(J$2,Models_Results!$B:$AP,$AC10,FALSE) -> -0.852 | K10: =HLOOKUP(K$2,Models_Results!$B:$AP,$AC10,FALSE) -> 0.185 | N10: =HLOOKUP(N$2,Models_Results!$B:$AP,$AC10,FALSE) -> 0.046 | O10: =HLOOKUP(O$2,Models_Results!$B:$AP,$AC10,FALSE) -> 0.093 | P10: =HLOOKUP(P$2,Models_Results!$B:$AP,$AC10,FALSE) -> -0.158 | Q10: =HLOOKUP(Q$2,Models_Results!$B:$AP,$AC10,FALSE) -> 0.372 | R10: =HLOOKUP(R$2,Models_Results!$B:$AP,$AC10,FALSE) -> -0.034 | S10: =HLOOKUP(S$2,Models_Results!$B:$AP,$AC10,FALSE) -> 0.259 | T10: =HLOOKUP(T$2,Models_Results!$B:$AP,$AC10,FALSE) -> 0.046 | U10: =HLOOKUP(U$2,Models_Results!$B:$AP,$AC10,FALSE) -> 0.093 | ... Y10: =HLOOKUP(Y$2,Models_Results!$B:$AP,$AC10,FALSE) -> 0.308 | AC10: 7
A11: =A10+0.25 -> 2026.5 | C11: =HLOOKUP(C$2,Models_Results!$B:$AP,$AC11,FALSE) -> -0.02 | D11: =HLOOKUP(D$2,Models_Results!$B:$AP,$AC11,FALSE) -> -0.224 | E11: =HLOOKUP(E$2,Models_Results!$B:$AP,$AC11,FALSE) -> -0.364 | F11: =HLOOKUP(F$2,Models_Results!$B:$AP,$AC11,FALSE) -> -0.067 | G11: =HLOOKUP(G$2,Models_Results!$B:$AP,$AC11,FALSE) -> -0.248 | H11: =HLOOKUP(H$2,Models_Results!$B:$AP,$AC11,FALSE) -> -0.435 | I11: =HLOOKUP(I$2,Models_Results!$B:$AP,$AC11,FALSE) -> -0.336 | J11: =HLOOKUP(J$2,Models_Results!$B:$AP,$AC11,FALSE) -> -0.907 | K11: =HLOOKUP(K$2,Models_Results!$B:$AP,$AC11,FALSE) -> 0.237 | N11: =HLOOKUP(N$2,Models_Results!$B:$AP,$AC11,FALSE) -> 0.165 | O11: =HLOOKUP(O$2,Models_Results!$B:$AP,$AC11,FALSE) -> 0.014 | P11: =HLOOKUP(P$2,Models_Results!$B:$AP,$AC11,FALSE) -> -0.04 | Q11: =HLOOKUP(Q$2,Models_Results!$B:$AP,$AC11,FALSE) -> 0.26 | R11: =HLOOKUP(R$2,Models_Results!$B:$AP,$AC11,FALSE) -> 0.083 | S11: =HLOOKUP(S$2,Models_Results!$B:$AP,$AC11,FALSE) -> 0.165 | T11: =HLOOKUP(T$2,Models_Results!$B:$AP,$AC11,FALSE) -> 0.165 | U11: =HLOOKUP(U$2,Models_Results!$B:$AP,$AC11,FALSE) -> 0.014 | ... Y11: =HLOOKUP(Y$2,Models_Results!$B:$AP,$AC11,FALSE) -> 0.209 | AC11: 8
A12: =A11+0.25 -> 2026.75 | C12: =HLOOKUP(C$2,Models_Results!$B:$AP,$AC12,FALSE) -> 0.034 | D12: =HLOOKUP(D$2,Models_Results!$B:$AP,$AC12,FALSE) -> -0.243 | E12: =HLOOKUP(E$2,Models_Results!$B:$AP,$AC12,FALSE) -> -0.337 | F12: =HLOOKUP(F$2,Models_Results!$B:$AP,$AC12,FALSE) -> -0.014 | G12: =HLOOKUP(G$2,Models_Results!$B:$AP,$AC12,FALSE) -> -0.273 | H12: =HLOOKUP(H$2,Models_Results!$B:$AP,$AC12,FALSE) -> -0.415 | I12: =HLOOKUP(I$2,Models_Results!$B:$AP,$AC12,FALSE) -> -0.328 | J12: =HLOOKUP(J$2,Models_Results!$B:$AP,$AC12,FALSE) -> -0.948 | K12: =HLOOKUP(K$2,Models_Results!$B:$AP,$AC12,FALSE) -> 0.297 | N12: =HLOOKUP(N$2,Models_Results!$B:$AP,$AC12,FALSE) -> 0.282 | O12: =HLOOKUP(O$2,Models_Results!$B:$AP,$AC12,FALSE) -> -0.054 | P12: =HLOOKUP(P$2,Models_Results!$B:$AP,$AC12,FALSE) -> 0.078 | Q12: =HLOOKUP(Q$2,Models_Results!$B:$AP,$AC12,FALSE) -> 0.157 | R12: =HLOOKUP(R$2,Models_Results!$B:$AP,$AC12,FALSE) -> 0.199 | S12: =HLOOKUP(S$2,Models_Results!$B:$AP,$AC12,FALSE) -> 0.081 | T12: =HLOOKUP(T$2,Models_Results!$B:$AP,$AC12,FALSE) -> 0.282 | U12: =HLOOKUP(U$2,Models_Results!$B:$AP,$AC12,FALSE) -> -0.054 | ... Y12: =HLOOKUP(Y$2,Models_Results!$B:$AP,$AC12,FALSE) -> 0.121 | AC12: 9
A13: =A12+0.25 -> 2027 | C13: =HLOOKUP(C$2,Models_Results!$B:$AP,$AC13,FALSE) -> 0.087 | D13: =HLOOKUP(D$2,Models_Results!$B:$AP,$AC13,FALSE) -> -0.259 | E13: =HLOOKUP(E$2,Models_Results!$B:$AP,$AC13,FALSE) -> -0.298 | F13: =HLOOKUP(F$2,Models_Results!$B:$AP,$AC13,FALSE) -> 0.039 | G13: =HLOOKUP(G$2,Models_Results!$B:$AP,$AC13,FALSE) -> -0.295 | H13: =HLOOKUP(H$2,Models_Results!$B:$AP,$AC13,FALSE) -> -0.382 | I13: =HLOOKUP(I$2,Models_Results!$B:$AP,$AC13,FALSE) -> -0.312 | J13: =HLOOKUP(J$2,Models_Results!$B:$AP,$AC13,FALSE) -> -0.975 | K13: =HLOOKUP(K$2,Models_Results!$B:$AP,$AC13,FALSE) -> 0.364 | N13: =HLOOKUP(N$2,Models_Results!$B:$AP,$AC13,FALSE) -> 0.396 | O13: =HLOOKUP(O$2,Models_Results!$B:$AP,$AC13,FALSE) -> -0.11 | P13: =HLOOKUP(P$2,Models_Results!$B:$AP,$AC13,FALSE) -> 0.197 | Q13: =HLOOKUP(Q$2,Models_Results!$B:$AP,$AC13,FALSE) -> 0.066 | R13: =HLOOKUP(R$2,Models_Results!$B:$AP,$AC13,FALSE) -> 0.313 | S13: =HLOOKUP(S$2,Models_Results!$B:$AP,$AC13,FALSE) -> 0.01 | T13: =HLOOKUP(T$2,Models_Results!$B:$AP,$AC13,FALSE) -> 0.396 | U13: =HLOOKUP(U$2,Models_Results!$B:$AP,$AC13,FALSE) -> -0.11 | ... Y13: =HLOOKUP(Y$2,Models_Results!$B:$AP,$AC13,FALSE) -> 0.044 | AC13: 10
A14: =A13+0.25 -> 2027.25 | C14: =HLOOKUP(C$2,Models_Results!$B:$AP,$AC14,FALSE) -> 0.138 | D14: =HLOOKUP(D$2,Models_Results!$B:$AP,$AC14,FALSE) -> -0.272 | E14: =HLOOKUP(E$2,Models_Results!$B:$AP,$AC14,FALSE) -> -0.25 | F14: =HLOOKUP(F$2,Models_Results!$B:$AP,$AC14,FALSE) -> 0.09 | G14: =HLOOKUP(G$2,Models_Results!$B:$AP,$AC14,FALSE) -> -0.313 | H14: =HLOOKUP(H$2,Models_Results!$B:$AP,$AC14,FALSE) -> -0.34 | I14: =HLOOKUP(I$2,Models_Results!$B:$AP,$AC14,FALSE) -> -0.287 | J14: =HLOOKUP(J$2,Models_Results!$B:$AP,$AC14,FALSE) -> -0.992 | K14: =HLOOKUP(K$2,Models_Results!$B:$AP,$AC14,FALSE) -> 0.435 | N14: =HLOOKUP(N$2,Models_Results!$B:$AP,$AC14,FALSE) -> 0.506 | O14: =HLOOKUP(O$2,Models_Results!$B:$AP,$AC14,FALSE) -> -0.155 | P14: =HLOOKUP(P$2,Models_Results!$B:$AP,$AC14,FALSE) -> 0.316 | Q14: =HLOOKUP(Q$2,Models_Results!$B:$AP,$AC14,FALSE) -> -0.014 | R14: =HLOOKUP(R$2,Models_Results!$B:$AP,$AC14,FALSE) -> 0.425 | S14: =HLOOKUP(S$2,Models_Results!$B:$AP,$AC14,FALSE) -> -0.051 | T14: =HLOOKUP(T$2,Models_Results!$B:$AP,$AC14,FALSE) -> 0.506 | U14: =HLOOKUP(U$2,Models_Results!$B:$AP,$AC14,FALSE) -> -0.155 | ... Y14: =HLOOKUP(Y$2,Models_Results!$B:$AP,$AC14,FALSE) -> -0.022 | AC14: 11
A15: =A14+0.25 -> 2027.5 | C15: =HLOOKUP(C$2,Models_Results!$B:$AP,$AC15,FALSE) -> 0.188 | D15: =HLOOKUP(D$2,Models_Results!$B:$AP,$AC15,FALSE) -> -0.281 | E15: =HLOOKUP(E$2,Models_Results!$B:$AP,$AC15,FALSE) -> -0.196 | F15: =HLOOKUP(F$2,Models_Results!$B:$AP,$AC15,FALSE) -> 0.141 | G15: =HLOOKUP(G$2,Models_Results!$B:$AP,$AC15,FALSE) -> -0.327 | H15: =HLOOKUP(H$2,Models_Results!$B:$AP,$AC15,FALSE) -> -0.29 | I15: =HLOOKUP(I$2,Models_Results!$B:$AP,$AC15,FALSE) -> -0.257 | J15: =HLOOKUP(J$2,Models_Results!$B:$AP,$AC15,FALSE) -> -1 | K15: =HLOOKUP(K$2,Models_Results!$B:$AP,$AC15,FALSE) -> 0.509 | N15: =HLOOKUP(N$2,Models_Results!$B:$AP,$AC15,FALSE) -> 0.612 | O15: =HLOOKUP(O$2,Models_Results!$B:$AP,$AC15,FALSE) -> -0.189 | P15: =HLOOKUP(P$2,Models_Results!$B:$AP,$AC15,FALSE) -> 0.436 | Q15: =HLOOKUP(Q$2,Models_Results!$B:$AP,$AC15,FALSE) -> -0.083 | R15: =HLOOKUP(R$2,Models_Results!$B:$AP,$AC15,FALSE) -> 0.534 | S15: =HLOOKUP(S$2,Models_Results!$B:$AP,$AC15,FALSE) -> -0.101 | T15: =HLOOKUP(T$2,Models_Results!$B:$AP,$AC15,FALSE) -> 0.612 | U15: =HLOOKUP(U$2,Models_Results!$B:$AP,$AC15,FALSE) -> -0.189 | ... Y15: =HLOOKUP(Y$2,Models_Results!$B:$AP,$AC15,FALSE) -> -0.077 | AC15: 12
A16: =A15+0.25 -> 2027.75 | C16: =HLOOKUP(C$2,Models_Results!$B:$AP,$AC16,FALSE) -> 0.236 | D16: =HLOOKUP(D$2,Models_Results!$B:$AP,$AC16,FALSE) -> -0.287 | E16: =HLOOKUP(E$2,Models_Results!$B:$AP,$AC16,FALSE) -> -0.136 | F16: =HLOOKUP(F$2,Models_Results!$B:$AP,$AC16,FALSE) -> 0.19 | G16: =HLOOKUP(G$2,Models_Results!$B:$AP,$AC16,FALSE) -> -0.338 | H16: =HLOOKUP(H$2,Models_Results!$B:$AP,$AC16,FALSE) -> -0.234 | I16: =HLOOKUP(I$2,Models_Results!$B:$AP,$AC16,FALSE) -> -0.222 | J16: =HLOOKUP(J$2,Models_Results!$B:$AP,$AC16,FALSE) -> -0.999 | K16: =HLOOKUP(K$2,Models_Results!$B:$AP,$AC16,FALSE) -> 0.584 | N16: =HLOOKUP(N$2,Models_Results!$B:$AP,$AC16,FALSE) -> 0.716 | O16: =HLOOKUP(O$2,Models_Results!$B:$AP,$AC16,FALSE) -> -0.213 | P16: =HLOOKUP(P$2,Models_Results!$B:$AP,$AC16,FALSE) -> 0.555 | Q16: =HLOOKUP(Q$2,Models_Results!$B:$AP,$AC16,FALSE) -> -0.142 | R16: =HLOOKUP(R$2,Models_Results!$B:$AP,$AC16,FALSE) -> 0.642 | S16: =HLOOKUP(S$2,Models_Results!$B:$AP,$AC16,FALSE) -> -0.141 | T16: =HLOOKUP(T$2,Models_Results!$B:$AP,$AC16,FALSE) -> 0.716 | U16: =HLOOKUP(U$2,Models_Results!$B:$AP,$AC16,FALSE) -> -0.213 | ... Y16: =HLOOKUP(Y$2,Models_Results!$B:$AP,$AC16,FALSE) -> -0.122 | AC16: 13
A17: =A16+0.25 -> 2028 | C17: =HLOOKUP(C$2,Models_Results!$B:$AP,$AC17,FALSE) -> 0.283 | D17: =HLOOKUP(D$2,Models_Results!$B:$AP,$AC17,FALSE) -> -0.289 | E17: =HLOOKUP(E$2,Models_Results!$B:$AP,$AC17,FALSE) -> -0.072 | F17: =HLOOKUP(F$2,Models_Results!$B:$AP,$AC17,FALSE) -> 0.239 | G17: =HLOOKUP(G$2,Models_Results!$B:$AP,$AC17,FALSE) -> -0.346 | H17: =HLOOKUP(H$2,Models_Results!$B:$AP,$AC17,FALSE) -> -0.174 | I17: =HLOOKUP(I$2,Models_Results!$B:$AP,$AC17,FALSE) -> -0.184 | J17: =HLOOKUP(J$2,Models_Results!$B:$AP,$AC17,FALSE) -> -0.991 | K17: =HLOOKUP(K$2,Models_Results!$B:$AP,$AC17,FALSE) -> 0.66 | N17: =HLOOKUP(N$2,Models_Results!$B:$AP,$AC17,FALSE) -> 0.816 | O17: =HLOOKUP(O$2,Models_Results!$B:$AP,$AC17,FALSE) -> -0.228 | P17: =HLOOKUP(P$2,Models_Results!$B:$AP,$AC17,FALSE) -> 0.674 | Q17: =HLOOKUP(Q$2,Models_Results!$B:$AP,$AC17,FALSE) -> -0.19 | R17: =HLOOKUP(R$2,Models_Results!$B:$AP,$AC17,FALSE) -> 0.748 | S17: =HLOOKUP(S$2,Models_Results!$B:$AP,$AC17,FALSE) -> -0.172 | T17: =HLOOKUP(T$2,Models_Results!$B:$AP,$AC17,FALSE) -> 0.816 | U17: =HLOOKUP(U$2,Models_Results!$B:$AP,$AC17,FALSE) -> -0.228 | ... Y17: =HLOOKUP(Y$2,Models_Results!$B:$AP,$AC17,FALSE) -> -0.158 | AC17: 14
A18: =A17+0.25 -> 2028.25 | C18: =HLOOKUP(C$2,Models_Results!$B:$AP,$AC18,FALSE) -> 0.329 | D18: =HLOOKUP(D$2,Models_Results!$B:$AP,$AC18,FALSE) -> -0.289 | E18: =HLOOKUP(E$2,Models_Results!$B:$AP,$AC18,FALSE) -> -0.006 | F18: =HLOOKUP(F$2,Models_Results!$B:$AP,$AC18,FALSE) -> 0.286 | G18: =HLOOKUP(G$2,Models_Results!$B:$AP,$AC18,FALSE) -> -0.35 | H18: =HLOOKUP(H$2,Models_Results!$B:$AP,$AC18,FALSE) -> -0.111 | I18: =HLOOKUP(I$2,Models_Results!$B:$AP,$AC18,FALSE) -> -0.142 | J18: =HLOOKUP(J$2,Models_Results!$B:$AP,$AC18,FALSE) -> -0.976 | K18: =HLOOKUP(K$2,Models_Results!$B:$AP,$AC18,FALSE) -> 0.736 | N18: =HLOOKUP(N$2,Models_Results!$B:$AP,$AC18,FALSE) -> 0.913 | O18: =HLOOKUP(O$2,Models_Results!$B:$AP,$AC18,FALSE) -> -0.233 | P18: =HLOOKUP(P$2,Models_Results!$B:$AP,$AC18,FALSE) -> 0.792 | Q18: =HLOOKUP(Q$2,Models_Results!$B:$AP,$AC18,FALSE) -> -0.228 | R18: =HLOOKUP(R$2,Models_Results!$B:$AP,$AC18,FALSE) -> 0.852 | S18: =HLOOKUP(S$2,Models_Results!$B:$AP,$AC18,FALSE) -> -0.192 | T18: =HLOOKUP(T$2,Models_Results!$B:$AP,$AC18,FALSE) -> 0.913 | U18: =HLOOKUP(U$2,Models_Results!$B:$AP,$AC18,FALSE) -> -0.233 | ... Y18: =HLOOKUP(Y$2,Models_Results!$B:$AP,$AC18,FALSE) -> -0.183 | AC18: 15
A19: =A18+0.25 -> 2028.5 | C19: =HLOOKUP(C$2,Models_Results!$B:$AP,$AC19,FALSE) -> 0.374 | D19: =HLOOKUP(D$2,Models_Results!$B:$AP,$AC19,FALSE) -> -0.286 | E19: =HLOOKUP(E$2,Models_Results!$B:$AP,$AC19,FALSE) -> 0.061 | F19: =HLOOKUP(F$2,Models_Results!$B:$AP,$AC19,FALSE) -> 0.333 | G19: =HLOOKUP(G$2,Models_Results!$B:$AP,$AC19,FALSE) -> -0.352 | H19: =HLOOKUP(H$2,Models_Results!$B:$AP,$AC19,FALSE) -> -0.045 | I19: =HLOOKUP(I$2,Models_Results!$B:$AP,$AC19,FALSE) -> -0.098 | J19: =HLOOKUP(J$2,Models_Results!$B:$AP,$AC19,FALSE) -> -0.956 | K19: =HLOOKUP(K$2,Models_Results!$B:$AP,$AC19,FALSE) -> 0.811 | N19: =HLOOKUP(N$2,Models_Results!$B:$AP,$AC19,FALSE) -> 1.007 | O19: =HLOOKUP(O$2,Models_Results!$B:$AP,$AC19,FALSE) -> -0.231 | P19: =HLOOKUP(P$2,Models_Results!$B:$AP,$AC19,FALSE) -> 0.911 | Q19: =HLOOKUP(Q$2,Models_Results!$B:$AP,$AC19,FALSE) -> -0.257 | R19: =HLOOKUP(R$2,Models_Results!$B:$AP,$AC19,FALSE) -> 0.954 | S19: =HLOOKUP(S$2,Models_Results!$B:$AP,$AC19,FALSE) -> -0.205 | T19: =HLOOKUP(T$2,Models_Results!$B:$AP,$AC19,FALSE) -> 1.007 | U19: =HLOOKUP(U$2,Models_Results!$B:$AP,$AC19,FALSE) -> -0.231 | ... Y19: =HLOOKUP(Y$2,Models_Results!$B:$AP,$AC19,FALSE) -> -0.2 | AC19: 16
A20: =A19+0.25 -> 2028.75 | C20: =HLOOKUP(C$2,Models_Results!$B:$AP,$AC20,FALSE) -> 0.417 | D20: =HLOOKUP(D$2,Models_Results!$B:$AP,$AC20,FALSE) -> -0.28 | E20: =HLOOKUP(E$2,Models_Results!$B:$AP,$AC20,FALSE) -> 0.13 | F20: =HLOOKUP(F$2,Models_Results!$B:$AP,$AC20,FALSE) -> 0.379 | G20: =HLOOKUP(G$2,Models_Results!$B:$AP,$AC20,FALSE) -> -0.351 | H20: =HLOOKUP(H$2,Models_Results!$B:$AP,$AC20,FALSE) -> 0.022 | I20: =HLOOKUP(I$2,Models_Results!$B:$AP,$AC20,FALSE) -> -0.052 | J20: =HLOOKUP(J$2,Models_Results!$B:$AP,$AC20,FALSE) -> -0.931 | K20: =HLOOKUP(K$2,Models_Results!$B:$AP,$AC20,FALSE) -> 0.886 | N20: =HLOOKUP(N$2,Models_Results!$B:$AP,$AC20,FALSE) -> 1.098 | O20: =HLOOKUP(O$2,Models_Results!$B:$AP,$AC20,FALSE) -> -0.221 | P20: =HLOOKUP(P$2,Models_Results!$B:$AP,$AC20,FALSE) -> 1.029 | Q20: =HLOOKUP(Q$2,Models_Results!$B:$AP,$AC20,FALSE) -> -0.276 | R20: =HLOOKUP(R$2,Models_Results!$B:$AP,$AC20,FALSE) -> 1.054 | S20: =HLOOKUP(S$2,Models_Results!$B:$AP,$AC20,FALSE) -> -0.208 | T20: =HLOOKUP(T$2,Models_Results!$B:$AP,$AC20,FALSE) -> 1.098 | U20: =HLOOKUP(U$2,Models_Results!$B:$AP,$AC20,FALSE) -> -0.221 | ... Y20: =HLOOKUP(Y$2,Models_Results!$B:$AP,$AC20,FALSE) -> -0.208 | AC20: 17
A21: =A20+0.25 -> 2029 | C21: =HLOOKUP(C$2,Models_Results!$B:$AP,$AC21,FALSE) -> 0.459 | D21: =HLOOKUP(D$2,Models_Results!$B:$AP,$AC21,FALSE) -> -0.272 | E21: =HLOOKUP(E$2,Models_Results!$B:$AP,$AC21,FALSE) -> 0.199 | F21: =HLOOKUP(F$2,Models_Results!$B:$AP,$AC21,FALSE) -> 0.424 | G21: =HLOOKUP(G$2,Models_Results!$B:$AP,$AC21,FALSE) -> -0.346 | H21: =HLOOKUP(H$2,Models_Results!$B:$AP,$AC21,FALSE) -> 0.091 | I21: =HLOOKUP(I$2,Models_Results!$B:$AP,$AC21,FALSE) -> -0.005 | J21: =HLOOKUP(J$2,Models_Results!$B:$AP,$AC21,FALSE) -> -0.901 | K21: =HLOOKUP(K$2,Models_Results!$B:$AP,$AC21,FALSE) -> 0.958 | N21: =HLOOKUP(N$2,Models_Results!$B:$AP,$AC21,FALSE) -> 1.186 | O21: =HLOOKUP(O$2,Models_Results!$B:$AP,$AC21,FALSE) -> -0.204 | P21: =HLOOKUP(P$2,Models_Results!$B:$AP,$AC21,FALSE) -> 1.147 | Q21: =HLOOKUP(Q$2,Models_Results!$B:$AP,$AC21,FALSE) -> -0.286 | R21: =HLOOKUP(R$2,Models_Results!$B:$AP,$AC21,FALSE) -> 1.152 | S21: =HLOOKUP(S$2,Models_Results!$B:$AP,$AC21,FALSE) -> -0.204 | T21: =HLOOKUP(T$2,Models_Results!$B:$AP,$AC21,FALSE) -> 1.186 | U21: =HLOOKUP(U$2,Models_Results!$B:$AP,$AC21,FALSE) -> -0.204 | ... Y21: =HLOOKUP(Y$2,Models_Results!$B:$AP,$AC21,FALSE) -> -0.208 | AC21: 18
... A105: =A104+0.25 -> 2050 | C105: =HLOOKUP(C$2,Models_Results!$B:$AP,$AC105,FALSE) -> 2.155 | D105: =HLOOKUP(D$2,Models_Results!$B:$AP,$AC105,FALSE) -> 3.285 | E105: =HLOOKUP(E$2,Models_Results!$B:$AP,$AC105,FALSE) -> 3.211 | F105: =HLOOKUP(F$2,Models_Results!$B:$AP,$AC105,FALSE) -> 2.63 | G105: =HLOOKUP(G$2,Models_Results!$B:$AP,$AC105,FALSE) -> 4.141 | H105: =HLOOKUP(H$2,Models_Results!$B:$AP,$AC105,FALSE) -> 4.182 | I105: =HLOOKUP(I$2,Models_Results!$B:$AP,$AC105,FALSE) -> 3.699 | J105: =HLOOKUP(J$2,Models_Results!$B:$AP,$AC105,FALSE) -> 5.694 | K105: =HLOOKUP(K$2,Models_Results!$B:$AP,$AC105,FALSE) -> 1.241 | N105: =HLOOKUP(N$2,Models_Results!$B:$AP,$AC105,FALSE) -> 3.746 | O105: =HLOOKUP(O$2,Models_Results!$B:$AP,$AC105,FALSE) -> 5.464 | P105: =HLOOKUP(P$2,Models_Results!$B:$AP,$AC105,FALSE) -> 7.147 | Q105: =HLOOKUP(Q$2,Models_Results!$B:$AP,$AC105,FALSE) -> 10.387 | R105: =HLOOKUP(R$2,Models_Results!$B:$AP,$AC105,FALSE) -> 6.147 | S105: =HLOOKUP(S$2,Models_Results!$B:$AP,$AC105,FALSE) -> 7.872 | T105: =HLOOKUP(T$2,Models_Results!$B:$AP,$AC105,FALSE) -> 3.746 | U105: =HLOOKUP(U$2,Models_Results!$B:$AP,$AC105,FALSE) -> 5.464 | ... Y105: =HLOOKUP(Y$2,Models_Results!$B:$AP,$AC105,FALSE) -> 8.653 | AC105: 102

Sheet Models_Results
A1: Variables__ | B1: Model_HumanCapital_epsi_ig___yd | C1: Model_HumanCapital_epsi_cge___yd | D1: Model_HumanCapital_epsi_cgrd___yd | E1: Model_HumanCapital_epsi_igCgrd___yd | F1: Model_HumanCapital_epsi_igCge___yd | G1: Model_HumanCapital_epsi_cgeCgrd___yd | H1: Model_HumanCapital_epsieff30y___yd | I1: Model_HumanCapital_epsieffcge30y___yd | J1: Model_HumanCapital_epsi_igeff30y___yd | K1: Model_HumanCapital_epsi_igeff25y___yd | L1: Model_HumanCapital_epsi_igeff10y___yd | M1: Model_HumanCapital_epsi_igeff5y___yd | N1: Model_HumanCapital_epsi_cgeeff30y___yd | O1: Model_HumanCapital_epsi_cgeeff25y___yd | P1: Model_HumanCapital_epsi_cgeeff10y___yd | Q1: Model_HumanCapital_epsi_cgeeff5y___yd | R1: Model_HumanCapital_epsi_cgeCgrd_limt___yd | S1: Model_HumanCapital_epsi_cgeCgrd_advt___yd | T1: Model_HumanCapital_epsi_cgrd_eff___yd | U1: EM_Model_HumanCapital_epsiig___yd | V1: EM_Model_HumanCapital_epsicge___yd | W1: EM_Model_HumanCapital_epsiigCge___yd | X1: EM_Model_HumanCapital_epsiigCgeVarShare___yd | Y1: EM_Model_HumanCapital_epsieff30y___yd | Z1: EM_Model_HumanCapital_epsieffcge30y___yd | AA1: EM_Model_HumanCapital_epsiigeff30y___yd | AB1: EM_Model_HumanCapital_epsiigeff25y___yd | AC1: EM_Model_HumanCapital_epsiigeff10y___yd | AD1: EM_Model_HumanCapital_epsiigeff5y___yd | AE1: EM_Model_HumanCapital_epsiigLAGeff10y___yd | AF1: EM_Model_HumanCapital_epsicgeeff30y___yd | AG1: EM_Model_HumanCapital_epsicgeeff25y___yd | AH1: EM_Model_HumanCapital_epsicgeeff10y___yd | AI1: EM_Model_HumanCapital_epsicgeeff5y___yd | AJ1: EM_Model_HumanCapital_epsicgeLAGeff10y___yd | AK1: EM_Model_HumanCapital_epsiigeff25ylow___yd | AL1: EM_Model_HumanCapital_epsiigeff10ylow___yd | AM1: EM_Model_HumanCapital_epsicgeeff25ylow___yd | AN1: EM_Model_HumanCapital_epsicgeeff10ylow___yd | AO1: EM_Model_HumanCapital_epsiiglow___yd | AP1: EM_Model_HumanCapital_epsicgelow___yd
A2: 0Q4 | B2: 0 | C2: 0 | D2: 0 | E2: 0 | F2: 0 | G2: 0 | H2: 0 | I2: 0 | J2: 0 | K2: 0 | L2: 0 | M2: 0 | N2: 0 | O2: 0 | P2: 0 | Q2: 0 | R2: 0 | S2: 0 | T2: 0 | U2: 0 | V2: 0 | W2: 0 | X2: 0 | Y2: 0 | Z2: 0 | AA2: 0 | AB2: 0 | AC2: 0 | AD2: 0 | AE2: 0 | AF2: 0 | AG2: 0 | AH2: 0 | AI2: 0 | AJ2: 0 | AK2: 0 | AL2: 0 | AM2: 0 | AN2: 0 | AO2: 0 | AP2: 0
A3: 1Q1 | B3: -0.083 | C3: 0.733 | D3: 0.649 | E3: 0.374 | F3: 0.352 | G3: 0.766 | H3: 0.058 | I3: 0.031 | J3: -0.027 | K3: -0.017 | L3: 0.057 | M3: 0.076 | N3: 0.77 | O3: 0.778 | P3: 0.856 | Q3: 0.932 | R3: -0.967 | S3: 2.564 | T3: 0.873 | U3: -0.744 | V3: 0.158 | W3: -0.331 | X3: -0.426 | Y3: 0.271 | Z3: -0.281 | AA3: -0.519 | AB3: -0.474 | AC3: -0.132 | AD3: -0.044 | AE3: 1.003 | AF3: -0.101 | AG3: -0.138 | AH3: -0.255 | AI3: -0.144 | AJ3: -0.845 | AK3: -0.389 | AL3: 0.046 | AM3: -0.222 | AN3: -0.359 | AO3: -0.744 | AP3: 0.158
A4: 1Q2 | B4: -0.238 | C4: -0.13 | D4: -0.302 | E4: -0.315 | F4: -0.192 | G4: -0.251 | H4: -0.015 | I4: 0.003 | J4: -0.253 | K4: -0.257 | L4: -0.282 | M4: -0.303 | N4: -0.128 | O4: -0.129 | P4: -0.138 | Q4: -0.152 | R4: 0.149 | S4: -0.616 | T4: -0.35 | U4: -0.288 | V4: 0.36 | W4: 0.054 | X4: 0.081 | Y4: -0.055 | Z4: 0.172 | AA4: -0.337 | AB4: -0.347 | AC4: -0.452 | AD4: -0.566 | AE4: -0.182 | AF4: 0.523 | AG4: 0.551 | AH4: 0.7 | AI4: 0.771 | AJ4: 0.539 | AK4: -0.367 | AL4: -0.502 | AM4: 0.609 | AN4: 0.8 | AO4: -0.288 | AP4: 0.36
A5: 1Q3 | B5: -0.188 | C5: -0.148 | D5: -0.343 | E5: -0.315 | F5: -0.176 | G5: -0.286 | H5: -0.015 | I5: 0.002 | J5: -0.204 | K5: -0.207 | L5: -0.232 | M5: -0.253 | N5: -0.148 | O5: -0.148 | P5: -0.159 | Q5: -0.174 | R5: 0.13 | S5: -0.699 | T5: -0.394 | U5: -0.191 | V5: 0.277 | W5: 0.062 | X5: 0.091 | Y5: -0.065 | Z5: 0.172 | AA5: -0.248 | AB5: -0.26 | AC5: -0.376 | AD5: -0.496 | AE5: -0.221 | AF5: 0.439 | AG5: 0.466 | AH5: 0.61 | AI5: 0.669 | AJ5: 0.536 | AK5: -0.282 | AL5: -0.433 | AM5: 0.523 | AN5: 0.705 | AO5: -0.191 | AP5: 0.277
A6: 1Q4 | B6: -0.132 | C6: -0.175 | D6: -0.369 | E6: -0.304 | F6: -0.161 | G6: -0.315 | H6: -0.016 | I6: 0.001 | J6: -0.148 | K6: -0.152 | L6: -0.177 | M6: -0.197 | N6: -0.176 | O6: -0.177 | P6: -0.189 | Q6: -0.206 | R6: 0.147 | S6: -0.782 | T6: -0.427 | U6: -0.075 | V6: 0.182 | W6: 0.073 | X6: 0.102 | Y6: -0.072 | Z6: 0.164 | AA6: -0.137 | AB6: -0.15 | AC6: -0.272 | AD6: -0.39 | AE6: -0.247 | AF6: 0.336 | AG6: 0.362 | AH6: 0.492 | AI6: 0.535 | AJ6: 0.51 | AK6: -0.174 | AL6: -0.332 | AM6: 0.415 | AN6: 0.579 | AO6: -0.075 | AP6: 0.182
A7: 2Q1 | B7: -0.075 | C7: -0.201 | D7: -0.376 | E7: -0.279 | F7: -0.146 | G7: -0.332 | H7: -0.017 | I7: -0.001 | J7: -0.092 | K7: -0.096 | L7: -0.122 | M7: -0.141 | N7: -0.204 | O7: -0.205 | P7: -0.22 | Q7: -0.239 | R7: 0.185 | S7: -0.852 | T7: -0.44 | U7: 0.046 | V7: 0.093 | W7: 0.089 | X7: 0.119 | Y7: -0.077 | Z7: 0.153 | AA7: -0.02 | AB7: -0.034 | AC7: -0.158 | AD7: -0.269 | AE7: -0.266 | AF7: 0.236 | AG7: 0.259 | AH7: 0.372 | AI7: 0.397 | AJ7: 0.474 | AK7: -0.059 | AL7: -0.219 | AM7: 0.308 | AN7: 0.45 | AO7: 0.046 | AP7: 0.093
A8: 2Q2 | B8: -0.02 | C8: -0.224 | D8: -0.364 | E8: -0.244 | F8: -0.13 | G8: -0.336 | H8: -0.018 | I8: -0.003 | J8: -0.037 | K8: -0.041 | L8: -0.067 | M8: -0.084 | N8: -0.229 | O8: -0.231 | P8: -0.248 | Q8: -0.27 | R8: 0.237 | S8: -0.907 | T8: -0.435 | U8: 0.165 | V8: 0.014 | W8: 0.109 | X8: 0.139 | Y8: -0.08 | Z8: 0.14 | AA8: 0.098 | AB8: 0.083 | AC8: -0.04 | AD8: -0.14 | AE8: -0.28 | AF8: 0.144 | AG8: 0.165 | AH8: 0.26 | AI8: 0.264 | AJ8: 0.434 | AK8: 0.057 | AL8: -0.102 | AM8: 0.209 | AN8: 0.327 | AO8: 0.165 | AP8: 0.014
A9: 2Q3 | B9: 0.034 | C9: -0.243 | D9: -0.337 | E9: -0.199 | F9: -0.113 | G9: -0.328 | H9: -0.018 | I9: -0.005 | J9: 0.017 | K9: 0.013 | L9: -0.014 | M9: -0.029 | N9: -0.251 | O9: -0.253 | P9: -0.273 | Q9: -0.298 | R9: 0.297 | S9: -0.948 | T9: -0.415 | U9: 0.282 | V9: -0.054 | W9: 0.134 | X9: 0.164 | Y9: -0.082 | Z9: 0.127 | AA9: 0.213 | AB9: 0.199 | AC9: 0.078 | AD9: -0.005 | AE9: -0.29 | AF9: 0.063 | AG9: 0.081 | AH9: 0.157 | AI9: 0.141 | AJ9: 0.392 | AK9: 0.173 | AL9: 0.018 | AM9: 0.121 | AN9: 0.214 | AO9: 0.282 | AP9: -0.054
