Workbook
Name BoxPlot: "BoxPlot"
Name Bubble: "Bubble"
Name Candlestick: "Candlestick"
Name Chart: "Chart"
Name ChartImage: "ChartImage"
Name ColumnRange: "ColumnRange"
Name Dumbbell: "Dumbbell"
Name Heatmap: "Heatmap"
Name Histogram: "Histogram"
Name Map: "Map"
Name OHLC: "OHLC"
Name PieChart: "PieChart"
Name Scatter: "Scatter"
Name Series: "Series"
Name Stripe: "Stripe"
Name Table: "Table"
Name TreeMap: "TreeMap"
Name Waterfall: "Waterfall"

Sheet Figure_6B_6D
A1: 1 | B1: 2 | C1: 3 | D1: 4 | E1: 5 | F1: 6 | G1: 7 | H1: 8 | I1: 9 | J1: 10 | K1: 11 | L1: 12 | M1: 13 | AO1: 6 | AR1: 2 | AY1: 2
A2: Variables -> | B2: =Results_from_model!N2 -> EM_Model_HumanCapital_epsiig___yd | C2: =Results_from_model!O2 -> EM_Model_HumanCapital_epsicge___yd | D2: =Results_from_model!P2 -> EM_Model_HumanCapital_epsiigeff30y___yd | E2: =Results_from_model!Q2 -> EM_Model_HumanCapital_epsicgeeff30y___yd | F2: =Results_from_model!R2 -> EM_Model_HumanCapital_epsiigeff25y___yd | G2: =Results_from_model!S2 -> EM_Model_HumanCapital_epsicgeeff25y___yd | H2: =Results_from_model!T2 -> EM_Model_HumanCapital_epsiiglow___yd | I2: =Results_from_model!U2 -> EM_Model_HumanCapital_epsicgelow___yd | J2: EM_Model_HumanCapital_epsiigeff15ylow___yd | K2: EM_Model_HumanCapital_epsicgeeff15ylow___yd | L2: =Results_from_model!X2 -> EM_Model_HumanCapital_epsiigeff25ylow___yd | M2: =Results_from_model!Y2 -> EM_Model_HumanCapital_epsicgeeff25ylow___yd | AO2: EM_Model_HumanCapital_epsiigeff25y___yd | AR2: EM_Model_HumanCapital_epsiig___yd | AY2: EM_Model_HumanCapital_epsiig___yd
A3: Comments ->
A4: Class[Size] -> | B4: Series[201-by-1] | C4: Series[201-by-1] | D4: Series[201-by-1] | E4: Series[201-by-1] | F4: Series[201-by-1] | G4: Series[201-by-1] | AO4: Series[201-by-1] | AR4: Series[201-by-1] | AY4: Series[201-by-1]
AN5: 0 | AQ5: 0 | AT5: 0 | AU5: 0 | AV5: 0 | AX5: 0
AN6: 0.058637732 | AQ6: -0.74619317 | AT6: 0.058637732 | AU6: 0.058637732 | AV6: 0.81577395 | AX6: 0.17262544
AN7: -0.45513589 | AQ7: -0.26584627 | AT7: -0.45513589 | AU7: -0.45513589 | AV7: -0.38340155 | AX7: 0.36843255
AN8: -0.39125716 | AQ8: -0.17377025 | AT8: -0.39125716 | AU8: -0.39125716 | AV8: -0.37922812 | AX8: 0.27752516
A9: 1Q4 | B9: =Results_from_model!N9 -> -0.063 | C9: =Results_from_model!O9 -> 0.177 | D9: =Results_from_model!P9 -> -0.457 | E9: =Results_from_model!Q9 -> 0.409 | F9: =Results_from_model!R9 -> -0.299 | G9: =Results_from_model!S9 -> 0.341 | H9: =Results_from_model!T9 -> -0.063 | I9: =Results_from_model!U9 -> 0.177 | ... M9: =Results_from_model!Y9 -> 0.366 | AN9: -0.29858589 | AO9: -0.299 | AQ9: -0.062858632 | AR9: -0.063 | AT9: -0.29858589 | AU9: -0.29858589 | AV9: -0.3507807 | AX9: 0.17650826 | AY9: -0.063
A10: 2Q1 | B10: =Results_from_model!N10 -> 0.052 | C10: =Results_from_model!O10 -> 0.082 | D10: =Results_from_model!P10 -> -0.356 | E10: =Results_from_model!Q10 -> 0.294 | F10: =Results_from_model!R10 -> -0.195 | G10: =Results_from_model!S10 -> 0.234 | H10: =Results_from_model!T10 -> 0.052 | I10: =Results_from_model!U10 -> 0.082 | ... M10: =Results_from_model!Y10 -> 0.256 | AN10: -0.1947674 | AO10: -0.195 | AQ10: 0.052203546 | AR10: 0.052 | AT10: -0.1947674 | AU10: -0.1947674 | AV10: -0.31180386 | AX10: 0.082186733 | AY10: 0.052
A11: 2Q2 | B11: =Results_from_model!N11 -> 0.166 | C11: =Results_from_model!O11 -> 0 | D11: =Results_from_model!P11 -> -0.246 | E11: =Results_from_model!Q11 -> 0.189 | F11: =Results_from_model!R11 -> -0.086 | G11: =Results_from_model!S11 -> 0.137 | H11: =Results_from_model!T11 -> 0.166 | I11: =Results_from_model!U11 -> 0 | ... M11: =Results_from_model!Y11 -> 0.157 | AN11: -0.086050326 | AO11: -0.086 | AQ11: 0.1664244 | AR11: 0.166 | AT11: -0.086050326 | AU11: -0.086050326 | AV11: -0.26725868 | AX11: -0.00016906579 | AY11: 0.166
A12: 2Q3 | B12: =Results_from_model!N12 -> 0.278 | C12: =Results_from_model!O12 -> -0.069 | D12: =Results_from_model!P12 -> -0.13 | E12: =Results_from_model!Q12 -> 0.096 | F12: =Results_from_model!R12 -> 0.025 | G12: =Results_from_model!S12 -> 0.053 | H12: =Results_from_model!T12 -> 0.278 | I12: =Results_from_model!U12 -> -0.069 | ... M12: =Results_from_model!Y12 -> 0.071 | AN12: 0.025309667 | AO12: 0.025 | AQ12: 0.27815626 | AR12: 0.278 | AT12: 0.025309667 | AU12: 0.025309667 | AV12: -0.21897394 | AX12: -0.069314085 | AY12: 0.278
A13: 2Q4 | B13: =Results_from_model!N13 -> 0.387 | C13: =Results_from_model!O13 -> -0.125 | D13: =Results_from_model!P13 -> -0.01 | E13: =Results_from_model!Q13 -> 0.016 | F13: =Results_from_model!R13 -> 0.138 | G13: =Results_from_model!S13 -> -0.019 | H13: =Results_from_model!T13 -> 0.387 | I13: =Results_from_model!U13 -> -0.125 | ... M13: =Results_from_model!Y13 -> -0.003 | AN13: 0.13845113 | AO13: 0.138 | AQ13: 0.38689786 | AR13: 0.387 | AT13: 0.13845113 | AU13: 0.13845113 | AV13: -0.16766294 | AX13: -0.12539323 | AY13: 0.387
A14: 3Q1 | B14: =Results_from_model!N14 -> 0.493 | C14: =Results_from_model!O14 -> -0.169 | D14: =Results_from_model!P14 -> 0.116 | E14: =Results_from_model!Q14 -> -0.052 | F14: =Results_from_model!R14 -> 0.253 | G14: =Results_from_model!S14 -> -0.078 | H14: =Results_from_model!T14 -> 0.493 | I14: =Results_from_model!U14 -> -0.169 | ... M14: =Results_from_model!Y14 -> -0.065 | R14: Infrastructure investment | S14: Human capital investment | AN14: 0.25300012 | AO14: 0.253 | AQ14: 0.49253816 | AR14: 0.493 | AT14: 0.25300012 | AU14: 0.25300012 | AV14: -0.11364135 | AX14: -0.16901331 | AY14: 0.493
A15: 3Q2 | B15: =Results_from_model!N15 -> 0.595 | C15: =Results_from_model!O15 -> -0.201 | D15: =Results_from_model!P15 -> 0.245 | E15: =Results_from_model!Q15 -> -0.108 | F15: =Results_from_model!R15 -> 0.369 | G15: =Results_from_model!S15 -> -0.125 | H15: =Results_from_model!T15 -> 0.595 | I15: =Results_from_model!U15 -> -0.201 | ... M15: =Results_from_model!Y15 -> -0.114 | P15: 2026 | Q15: 1Q4 | R15: =B9 -> -0.063 | S15: =C9 -> 0.177 | AN15: 0.36875553 | AO15: 0.369 | AQ15: 0.59509751 | AR15: 0.595 | AT15: 0.36875553 | AU15: 0.36875553 | AV15: -0.057082047 | AX15: -0.20091586 | AY15: 0.595
A16: 3Q3 | B16: =Results_from_model!N16 -> 0.695 | C16: =Results_from_model!O16 -> -0.222 | D16: =Results_from_model!P16 -> 0.378 | E16: =Results_from_model!Q16 -> -0.152 | F16: =Results_from_model!R16 -> 0.486 | G16: =Results_from_model!S16 -> -0.16 | H16: =Results_from_model!T16 -> 0.695 | I16: =Results_from_model!U16 -> -0.222 | ... M16: =Results_from_model!Y16 -> -0.153 | P16: 2030 | Q16: 5Q4 | R16: =B25 -> 1.468 | S16: =C25 -> -0.028 | AN16: 0.48558031 | AO16: 0.486 | AQ16: 0.69463949 | AR16: 0.695 | AT16: 0.48558031 | AU16: 0.48558031 | AV16: 0.0018945859 | AX16: -0.22186229 | AY16: 0.695
A17: 3Q4 | B17: =Results_from_model!N17 -> 0.791 | C17: =Results_from_model!O17 -> -0.233 | D17: =Results_from_model!P17 -> 0.514 | E17: =Results_from_model!Q17 -> -0.185 | F17: =Results_from_model!R17 -> 0.603 | G17: =Results_from_model!S17 -> -0.186 | H17: =Results_from_model!T17 -> 0.791 | I17: =Results_from_model!U17 -> -0.233 | ... M17: =Results_from_model!Y17 -> -0.18 | P17: 2040 | Q17: 15Q4 | R17: =B65 -> 3.183 | S17: =C65 -> 3.333 | AN17: 0.60336389 | AO17: 0.603 | AQ17: 0.79124102 | AR17: 0.791 | AT17: 0.60336389 | AU17: 0.60336389 | AV17: 0.063188728 | AX17: -0.23259429 | AY17: 0.791
A18: 4Q1 | B18: =Results_from_model!N18 -> 0.885 | C18: =Results_from_model!O18 -> -0.234 | D18: =Results_from_model!P18 -> 0.653 | E18: =Results_from_model!Q18 -> -0.208 | F18: =Results_from_model!R18 -> 0.722 | G18: =Results_from_model!S18 -> -0.201 | H18: =Results_from_model!T18 -> 0.885 | I18: =Results_from_model!U18 -> -0.234 | ... M18: =Results_from_model!Y18 -> -0.197 | P18: 2050 | Q18: 25Q4 | R18: =B105 -> 3.666 | S18: =C105 -> 5.698 | AN18: 0.72200909 | AO18: 0.722 | AQ18: 0.88498219 | AR18: 0.885 | AT18: 0.72200909 | AU18: 0.72200909 | AV18: 0.12670979 | AX18: -0.23382082 | AY18: 0.885
A19: 4Q2 | B19: =Results_from_model!N19 -> 0.976 | C19: =Results_from_model!O19 -> -0.226 | D19: =Results_from_model!P19 -> 0.795 | E19: =Results_from_model!Q19 -> -0.221 | F19: =Results_from_model!R19 -> 0.841 | G19: =Results_from_model!S19 -> -0.206 | H19: =Results_from_model!T19 -> 0.976 | I19: =Results_from_model!U19 -> -0.226 | ... M19: =Results_from_model!Y19 -> -0.205 | AN19: 0.84142743 | AO19: 0.841 | AQ19: 0.97594285 | AR19: 0.976 | AT19: 0.84142743 | AU19: 0.84142743 | AV19: 0.19237236 | AX19: -0.22621474 | AY19: 0.976
A20: 4Q3 | B20: =Results_from_model!N20 -> 1.064 | C20: =Results_from_model!O20 -> -0.21 | D20: =Results_from_model!P20 -> 0.94 | E20: =Results_from_model!Q20 -> -0.224 | F20: =Results_from_model!R20 -> 0.962 | G20: =Results_from_model!S20 -> -0.203 | H20: =Results_from_model!T20 -> 1.064 | I20: =Results_from_model!U20 -> -0.21 | ... M20: =Results_from_model!Y20 -> -0.204 | AN20: 0.96153719 | AO20: 0.962 | AQ20: 1.0642014 | AR20: 1.064 | AT20: 0.96153719 | AU20: 0.96153719 | AV20: 0.26009466 | AX20: -0.21041271 | AY20: 1.064
A21: 4Q4 | B21: =Results_from_model!N21 -> 1.15 | C21: =Results_from_model!O21 -> -0.187 | D21: =Results_from_model!P21 -> 1.088 | E21: =Results_from_model!Q21 -> -0.219 | F21: =Results_from_model!R21 -> 1.082 | G21: =Results_from_model!S21 -> -0.191 | H21: =Results_from_model!T21 -> 1.15 | I21: =Results_from_model!U21 -> -0.187 | ... M21: =Results_from_model!Y21 -> -0.194 | AN21: 1.0822626 | AO21: 1.082 | AQ21: 1.1498345 | AR21: 1.15 | AT21: 1.0822626 | AU21: 1.0822626 | AV21: 0.32979794 | AX21: -0.18701624 | AY21: 1.15
A22: 5Q1 | B22: =Results_from_model!N22 -> 1.233 | C22: =Results_from_model!O22 -> -0.157 | D22: =Results_from_model!P22 -> 1.238 | E22: =Results_from_model!Q22 -> -0.205 | F22: =Results_from_model!R22 -> 1.204 | G22: =Results_from_model!S22 -> -0.172 | H22: =Results_from_model!T22 -> 1.233 | I22: =Results_from_model!U22 -> -0.157 | ... M22: =Results_from_model!Y22 -> -0.176 | AN22: 1.2035333 | AO22: 1.204 | AQ22: 1.2329167 | AR22: 1.233 | AT22: 1.2035333 | AU22: 1.2035333 | AV22: 0.40140613 | AX22: -0.15659322 | AY22: 1.233
A23: 5Q2 | B23: =Results_from_model!N23 -> 1.314 | C23: =Results_from_model!O23 -> -0.12 | D23: =Results_from_model!P23 -> 1.39 | E23: =Results_from_model!Q23 -> -0.183 | F23: =Results_from_model!R23 -> 1.325 | G23: =Results_from_model!S23 -> -0.145 | H23: =Results_from_model!T23 -> 1.314 | I23: =Results_from_model!U23 -> -0.12 | ... M23: =Results_from_model!Y23 -> -0.151 | AN23: 1.3252839 | AO23: 1.325 | AQ23: 1.3135208 | AR23: 1.314 | AT23: 1.3252839 | AU23: 1.3252839 | AV23: 0.4748456 | AX23: -0.11967946 | AY23: 1.314
A24: 5Q3 | B24: =Results_from_model!N24 -> 1.392 | C24: =Results_from_model!O24 -> -0.077 | D24: =Results_from_model!P24 -> 1.544 | E24: =Results_from_model!Q24 -> -0.153 | F24: =Results_from_model!R24 -> 1.447 | G24: =Results_from_model!S24 -> -0.111 | H24: =Results_from_model!T24 -> 1.392 | I24: =Results_from_model!U24 -> -0.077 | ... M24: =Results_from_model!Y24 -> -0.118 | AN24: 1.4474536 | AO24: 1.447 | AQ24: 1.3917174 | AR24: 1.392 | AT24: 1.4474536 | AU24: 1.4474536 | AV24: 0.55004491 | AX24: -0.076780229 | AY24: 1.392
A25: 5Q4 | B25: =Results_from_model!N25 -> 1.468 | C25: =Results_from_model!O25 -> -0.028 | D25: =Results_from_model!P25 -> 1.7 | E25: =Results_from_model!Q25 -> -0.117 | F25: =Results_from_model!R25 -> 1.57 | G25: =Results_from_model!S25 -> -0.071 | H25: =Results_from_model!T25 -> 1.468 | I25: =Results_from_model!U25 -> -0.028 | ... M25: =Results_from_model!Y25 -> -0.079 | AN25: 1.5699859 | AO25: 1.57 | AQ25: 1.4675754 | AR25: 1.468 | AT25: 1.5699859 | AU25: 1.5699859 | AV25: 0.62693464 | AX25: -0.028371803 | AY25: 1.468
A26: 6Q1 | B26: =Results_from_model!N26 -> 1.541 | C26: =Results_from_model!O26 -> 0.025 | D26: =Results_from_model!P26 -> 1.858 | E26: =Results_from_model!Q26 -> -0.073 | F26: =Results_from_model!R26 -> 1.693 | G26: =Results_from_model!S26 -> -0.024 | H26: =Results_from_model!T26 -> 1.541 | I26: =Results_from_model!U26 -> 0.025 | ... M26: =Results_from_model!Y26 -> -0.034 | AN26: 1.6928283 | AO26: 1.693 | AQ26: 1.5411617 | AR26: 1.541 | AT26: 1.6928283 | AU26: 1.6928283 | AV26: 0.70544709 | AX26: 0.025097116 | AY26: 1.541
A27: 6Q2 | B27: =Results_from_model!N27 -> 1.613 | C27: =Results_from_model!O27 -> 0.083 | D27: =Results_from_model!P27 -> 2.017 | E27: =Results_from_model!Q27 -> -0.023 | F27: =Results_from_model!R27 -> 1.816 | G27: =Results_from_model!S27 -> 0.028 | H27: =Results_from_model!T27 -> 1.613 | I27: =Results_from_model!U27 -> 0.083 | ... M27: =Results_from_model!Y27 -> 0.017 | AN27: 1.8159321 | AO27: 1.816 | AQ27: 1.6125414 | AR27: 1.613 | AT27: 1.8159321 | AU27: 1.8159321 | AV27: 0.78551605 | AX27: 0.083204007 | AY27: 1.613
A28: 6Q3 | B28: =Results_from_model!N28 -> 1.682 | C28: =Results_from_model!O28 -> 0.146 | D28: =Results_from_model!P28 -> 2.178 | E28: =Results_from_model!Q28 -> 0.033 | F28: =Results_from_model!R28 -> 1.939 | G28: =Results_from_model!S28 -> 0.085 | H28: =Results_from_model!T28 -> 1.682 | I28: =Results_from_model!U28 -> 0.146 | ... M28: =Results_from_model!Y28 -> 0.074 | AN28: 1.9392519 | AO28: 1.939 | AQ28: 1.6817776 | AR28: 1.682 | AT28: 1.9392519 | AU28: 1.9392519 | AV28: 0.86707649 | AX28: 0.14555121 | AY28: 1.682
A29: 6Q4 | B29: =Results_from_model!N29 -> 1.749 | C29: =Results_from_model!O29 -> 0.212 | D29: =Results_from_model!P29 -> 2.341 | E29: =Results_from_model!Q29 -> 0.094 | F29: =Results_from_model!R29 -> 2.063 | G29: =Results_from_model!S29 -> 0.147 | H29: =Results_from_model!T29 -> 1.749 | I29: =Results_from_model!U29 -> 0.212 | ... M29: =Results_from_model!Y29 -> 0.136 | AN29: 2.0627457 | AO29: 2.063 | AQ29: 1.748932 | AR29: 1.749 | AT29: 2.0627457 | AU29: 2.0627457 | AV29: 0.95006426 | AX29: 0.21176466 | AY29: 1.749
A30: 7Q1 | B30: =Results_from_model!N30 -> 1.814 | C30: =Results_from_model!O30 -> 0.281 | D30: =Results_from_model!P30 -> 2.504 | E30: =Results_from_model!Q30 -> 0.161 | F30: =Results_from_model!R30 -> 2.186 | G30: =Results_from_model!S30 -> 0.214 | H30: =Results_from_model!T30 -> 1.814 | I30: =Results_from_model!U30 -> 0.281 | ... M30: =Results_from_model!Y30 -> 0.203 | AN30: 2.1863743 | AO30: 2.186 | AQ30: 1.8140644 | AR30: 1.814 | AT30: 2.1863743 | AU30: 2.1863743 | AV30: 1.0344158 | AX30: 0.2814927 | AY30: 1.814
... A43: 10Q2 | B43: =Results_from_model!N43 -> 2.501 | C43: =Results_from_model!O43 -> 1.382 | D43: =Results_from_model!P43 -> 4.714 | E43: =Results_from_model!Q43 -> 1.394 | F43: =Results_from_model!R43 -> 3.792 | G43: =Results_from_model!S43 -> 1.381 | H43: =Results_from_model!T43 -> 2.501 | I43: =Results_from_model!U43 -> 1.382 | ... M43: =Results_from_model!Y43 -> 1.383 | AN43: 3.7923185 | AO43: 3.792 | AQ43: 2.5011896 | AR43: 2.501 | AT43: 3.7923185 | AU43: 3.7923185 | AV43: 2.2260341 | AX43: 1.382034 | AY43: 2.501
A44: 10Q3 | B44: =Results_from_model!N44 -> 2.543 | C44: =Results_from_model!O44 -> 1.474 | D44: =Results_from_model!P44 -> 4.888 | E44: =Results_from_model!Q44 -> 1.508 | F44: =Results_from_model!R44 -> 3.915 | G44: =Results_from_model!S44 -> 1.486 | H44: =Results_from_model!T44 -> 2.543 | I44: =Results_from_model!U44 -> 1.474 | ... M44: =Results_from_model!Y44 -> 1.491 | R44: Infrastructure investment | S44: Human capital investment | AB44: Figure 6D | AN44: 3.9149808 | AO44: 3.915 | AQ44: 2.543451 | AR44: 2.543 | AT44: 3.9149808 | AU44: 3.9149808 | AV44: 2.3232793 | AX44: 1.4741412 | AY44: 2.543
A45: 10Q4 | B45: =Results_from_model!N45 -> 2.584 | C45: =Results_from_model!O45 -> 1.567 | D45: =Results_from_model!P45 -> 5.063 | E45: =Results_from_model!Q45 -> 1.625 | F45: =Results_from_model!R45 -> 4.037 | G45: =Results_from_model!S45 -> 1.592 | H45: =Results_from_model!T45 -> 2.584 | I45: =Results_from_model!U45 -> 1.567 | ... M45: =Results_from_model!Y45 -> 1.599 | O45: 25Q4 | P45: 0.8 | Q45: Initial efficiency: 0.8 (Baseline) | R45: =VLOOKUP($O45,$A:$G,2,FALSE) -> 3.666 | S45: =VLOOKUP($O45,$A:$G,3,FALSE) -> 5.698 | AN45: 4.0374369 | AO45: 4.037 | AQ45: 2.5844139 | AR45: 2.584 | AT45: 4.0374369 | AU45: 4.0374369 | AV45: 2.4218229 | AX45: 1.5665025 | AY45: 2.584
A46: 11Q1 | B46: =Results_from_model!N46 -> 2.624 | C46: =Results_from_model!O46 -> 1.659 | D46: =Results_from_model!P46 -> 5.238 | E46: =Results_from_model!Q46 -> 1.744 | F46: =Results_from_model!R46 -> 4.16 | G46: =Results_from_model!S46 -> 1.699 | H46: =Results_from_model!T46 -> 2.624 | I46: =Results_from_model!U46 -> 1.659 | ... M46: =Results_from_model!Y46 -> 1.709 | O46: 25Q4 | P46: 1 | Q46: Closing gap by 2050 | R46: =VLOOKUP($O46,$A:$G,6,FALSE) -> 10.972 | S46: =VLOOKUP($O46,$A:$G,7,FALSE) -> 7.985 | AN46: 4.1596753 | AO46: 4.16 | AQ46: 2.6241166 | AR46: 2.624 | AT46: 4.1596753 | AU46: 4.1596753 | AV46: 2.5588741 | AX46: 1.658998 | AY46: 2.624
A47: 11Q2 | B47: =Results_from_model!N47 -> 2.663 | C47: =Results_from_model!O47 -> 1.752 | D47: =Results_from_model!P47 -> 5.413 | E47: =Results_from_model!Q47 -> 1.864 | F47: =Results_from_model!R47 -> 4.282 | G47: =Results_from_model!S47 -> 1.808 | H47: =Results_from_model!T47 -> 2.663 | I47: =Results_from_model!U47 -> 1.752 | ... M47: =Results_from_model!Y47 -> 1.821 | O47: 25Q4 | P47: 1 | Q47: Closing gap by 2035 | R47: =VLOOKUP($O47,$A:$G,4,FALSE) -> 13.177 | S47: =VLOOKUP($O47,$A:$G,5,FALSE) -> 9.438 | AN47: 4.2816851 | AO47: 4.282 | AQ47: 2.6625963 | AR47: 2.663 | AT47: 4.2816851 | AU47: 4.2816851 | AV47: 2.702942 | AX47: 1.7515164 | AY47: 2.663
A48: 11Q3 | B48: =Results_from_model!N48 -> 2.7 | C48: =Results_from_model!O48 -> 1.844 | D48: =Results_from_model!P48 -> 5.589 | E48: =Results_from_model!Q48 -> 1.986 | F48: =Results_from_model!R48 -> 4.403 | G48: =Results_from_model!S48 -> 1.917 | H48: =Results_from_model!T48 -> 2.7 | I48: =Results_from_model!U48 -> 1.844 | ... M48: =Results_from_model!Y48 -> 1.933 | R48: =R47-R46 -> 2.205 | AN48: 4.4034566 | AO48: 4.403 | AQ48: 2.6998895 | AR48: 2.7 | AT48: 4.4034566 | AU48: 4.4034566 | AV48: 2.8489663 | AX48: 1.843954 | AY48: 2.7
A49: 11Q4 | B49: =Results_from_model!N49 -> 2.736 | C49: =Results_from_model!O49 -> 1.936 | D49: =Results_from_model!P49 -> 5.766 | E49: =Results_from_model!Q49 -> 2.109 | F49: =Results_from_model!R49 -> 4.525 | G49: =Results_from_model!S49 -> 2.027 | H49: =Results_from_model!T49 -> 2.736 | I49: =Results_from_model!U49 -> 1.936 | ... M49: =Results_from_model!Y49 -> 2.046 | AN49: 4.5249808 | AO49: 4.525 | AQ49: 2.7360312 | AR49: 2.736 | AT49: 4.5249808 | AU49: 4.5249808 | AV49: 2.9954627 | AX49: 1.9362148 | AY49: 2.736
A50: 12Q1 | B50: =Results_from_model!N50 -> 2.771 | C50: =Results_from_model!O50 -> 2.028 | D50: =Results_from_model!P50 -> 5.943 | E50: =Results_from_model!Q50 -> 2.234 | F50: =Results_from_model!R50 -> 4.646 | G50: =Results_from_model!S50 -> 2.138 | H50: =Results_from_model!T50 -> 2.771 | I50: =Results_from_model!U50 -> 2.028 | ... M50: =Results_from_model!Y50 -> 2.161 | R50: Infrastructure investment | S50: Human capital investment | AN50: 4.6462496 | AO50: 4.646 | AQ50: 2.7710559 | AR50: 2.771 | AT50: 4.6462496 | AU50: 4.6462496 | AV50: 3.1419935 | AX50: 2.0282098 | AY50: 2.771
A51: 12Q2 | B51: =Results_from_model!N51 -> 2.805 | C51: =Results_from_model!O51 -> 2.12 | D51: =Results_from_model!P51 -> 6.12 | E51: =Results_from_model!Q51 -> 2.36 | F51: =Results_from_model!R51 -> 4.767 | G51: =Results_from_model!S51 -> 2.25 | H51: =Results_from_model!T51 -> 2.805 | I51: =Results_from_model!U51 -> 2.12 | ... M51: =Results_from_model!Y51 -> 2.276 | O51: 25Q4 | P51: 0.6 | Q51: Initial efficiency: 0.6 | R51: =VLOOKUP($O51,$A:$M,8,FALSE) -> 3.666 | S51: =VLOOKUP($O51,$A:$M,9,FALSE) -> 5.698 | AN51: 4.7672555 | AO51: 4.767 | AQ51: 2.8049968 | AR51: 2.805 | AT51: 4.7672555 | AU51: 4.7672555 | AV51: 3.2884247 | AX51: 2.1198565 | AY51: 2.805
A52: 12Q3 | B52: =Results_from_model!N52 -> 2.838 | C52: =Results_from_model!O52 -> 2.211 | D52: =Results_from_model!P52 -> 6.298 | E52: =Results_from_model!Q52 -> 2.487 | F52: =Results_from_model!R52 -> 4.888 | G52: =Results_from_model!S52 -> 2.362 | H52: =Results_from_model!T52 -> 2.838 | I52: =Results_from_model!U52 -> 2.211 | ... M52: =Results_from_model!Y52 -> 2.391 | O52: 25Q4 | P52: 0.8 | Q52: Closing gap by 2050 | R52: =VLOOKUP($O52,$A:$M,12,FALSE) -> 12.232 | S52: =VLOOKUP($O52,$A:$M,13,FALSE) -> 8.354 | AN52: 4.8879918 | AO52: 4.888 | AQ52: 2.8378863 | AR52: 2.838 | AT52: 4.8879918 | AU52: 4.8879918 | AV52: 3.4347095 | AX52: 2.2110786 | AY52: 2.838
...

Sheet Figure_6A_6C_6E_6F
A1: 1 | B1: 2 | C1: 3 | D1: 4 | E1: 5 | F1: 6 | G1: 7 | H1: 8 | I1: 9
A2: AE | B2: Variables -> | C2: =Results_from_model!C2 -> Model_HumanCapital_epsi_ig___yd | D2: =Results_from_model!D2 -> Model_HumanCapital_epsi_cge___yd | E2: =Results_from_model!E2 -> Model_HumanCapital_epsi_cgrd___yd | F2: =Results_from_model!F2 -> Model_HumanCapital_epsi_igeff25y___yd | G2: =Results_from_model!G2 -> Model_HumanCapital_epsi_cgeeff25y___yd | H2: =Results_from_model!H2 -> Model_HumanCapital_epsi_cgrd_eff25y___yd | I2: =Results_from_model!I2 -> Model_HumanCapital_epsi_cgeCgrd___yd | J2: =Results_from_model!J2 -> Model_HumanCapital_epsicgrd_cge_adt___yd | K2: =Results_from_model!K2 -> Model_HumanCapital_epsicgrd_cge_limt___yd | AB2: Figure 6A | AN2: Figure 6B
B3: Comments ->
B4: Class[Size] -> | C4: Series[201-by-1] | D4: Series[201-by-1] | E4: Series[201-by-1] | F4: Series[201-by-1] | G4: Series[201-by-1] | I4: Series[2002-by-1]
V8: Infrastructure investment | W8: Human capital investment | X8: R&D spending
A9: 2026 | C9: =Results_from_model!C9 -> -0.091 | D9: =Results_from_model!D9 -> 0.026 | E9: =Results_from_model!E9 -> -0.363 | F9: =Results_from_model!F9 -> -0.169 | G9: =Results_from_model!G9 -> 0.083 | H9: =Results_from_model!H9 -> -0.395 | I9: =Results_from_model!I9 -> -0.199 | J9: =Results_from_model!J9 -> -0.649 | K9: =Results_from_model!K9 -> 0.231 | T9: 2026 | U9: 1Q4 | V9: =C9 -> -0.091 | W9: =D9 -> 0.026 | X9: =E9 -> -0.363 | Y9: =I9 -> -0.199
A10: =A9+0.25 -> 2026.25 | C10: =Results_from_model!C10 -> -0.048 | D10: =Results_from_model!D10 -> -0.031 | E10: =Results_from_model!E10 -> -0.37 | F10: =Results_from_model!F10 -> -0.131 | G10: =Results_from_model!G10 -> 0.02 | H10: =Results_from_model!H10 -> -0.408 | I10: =Results_from_model!I10 -> -0.232 | J10: =Results_from_model!J10 -> -0.747 | K10: =Results_from_model!K10 -> 0.262 | T10: 2030 | U10: 5Q4 | V10: =C25 -> 0.489 | W10: =D25 -> -0.253 | X10: =E25 -> 0.546 | Y10: =I25 -> 0.219
A11: =A10+0.25 -> 2026.5 | C11: =Results_from_model!C11 -> -0.005 | D11: =Results_from_model!D11 -> -0.082 | E11: =Results_from_model!E11 -> -0.356 | F11: =Results_from_model!F11 -> -0.093 | G11: =Results_from_model!G11 -> -0.038 | H11: =Results_from_model!H11 -> -0.4 | I11: =Results_from_model!I11 -> -0.25 | J11: =Results_from_model!J11 -> -0.821 | K11: =Results_from_model!K11 -> 0.307 | T11: 2040 | U11: 15Q4 | V11: =C65 -> 1.277 | W11: =D65 -> 1.407 | X11: =E65 -> 2.424 | Y11: =I65 -> 2.239
A12: =A11+0.25 -> 2026.75 | C12: =Results_from_model!C12 -> 0.037 | D12: =Results_from_model!D12 -> -0.127 | E12: =Results_from_model!E12 -> -0.326 | F12: =Results_from_model!F12 -> -0.054 | G12: =Results_from_model!G12 -> -0.09 | H12: =Results_from_model!H12 -> -0.375 | I12: =Results_from_model!I12 -> -0.253 | J12: =Results_from_model!J12 -> -0.878 | K12: =Results_from_model!K12 -> 0.361 | T12: 2050 | U12: 25Q4 | V12: =C105 -> 1.64 | W12: =D105 -> 3.158 | X12: =E105 -> 3.195 | Y12: =I105 -> 3.69
A13: =A12+0.25 -> 2027 | C13: =Results_from_model!C13 -> 0.078 | D13: =Results_from_model!D13 -> -0.166 | E13: =Results_from_model!E13 -> -0.282 | F13: =Results_from_model!F13 -> -0.016 | G13: =Results_from_model!G13 -> -0.136 | H13: =Results_from_model!H13 -> -0.336 | I13: =Results_from_model!I13 -> -0.246 | J13: =Results_from_model!J13 -> -0.918 | K13: =Results_from_model!K13 -> 0.424
A14: =A13+0.25 -> 2027.25 | C14: =Results_from_model!C14 -> 0.117 | D14: =Results_from_model!D14 -> -0.198 | E14: =Results_from_model!E14 -> -0.229 | F14: =Results_from_model!F14 -> 0.023 | G14: =Results_from_model!G14 -> -0.176 | H14: =Results_from_model!H14 -> -0.288 | I14: =Results_from_model!I14 -> -0.229 | J14: =Results_from_model!J14 -> -0.946 | K14: =Results_from_model!K14 -> 0.491
A15: =A14+0.25 -> 2027.5 | C15: =Results_from_model!C15 -> 0.156 | D15: =Results_from_model!D15 -> -0.225 | E15: =Results_from_model!E15 -> -0.169 | F15: =Results_from_model!F15 -> 0.061 | G15: =Results_from_model!G15 -> -0.21 | H15: =Results_from_model!H15 -> -0.232 | I15: =Results_from_model!I15 -> -0.206 | J15: =Results_from_model!J15 -> -0.962 | K15: =Results_from_model!K15 -> 0.562
A16: =A15+0.25 -> 2027.75 | C16: =Results_from_model!C16 -> 0.193 | D16: =Results_from_model!D16 -> -0.247 | E16: =Results_from_model!E16 -> -0.103 | F16: =Results_from_model!F16 -> 0.098 | G16: =Results_from_model!G16 -> -0.239 | H16: =Results_from_model!H16 -> -0.17 | I16: =Results_from_model!I16 -> -0.177 | J16: =Results_from_model!J16 -> -0.969 | K16: =Results_from_model!K16 -> 0.636
A17: =A16+0.25 -> 2028 | C17: =Results_from_model!C17 -> 0.23 | D17: =Results_from_model!D17 -> -0.264 | E17: =Results_from_model!E17 -> -0.034 | F17: =Results_from_model!F17 -> 0.136 | G17: =Results_from_model!G17 -> -0.263 | H17: =Results_from_model!H17 -> -0.104 | I17: =Results_from_model!I17 -> -0.143 | J17: =Results_from_model!J17 -> -0.967 | K17: =Results_from_model!K17 -> 0.71
A18: =A17+0.25 -> 2028.25 | C18: =Results_from_model!C18 -> 0.265 | D18: =Results_from_model!D18 -> -0.276 | E18: =Results_from_model!E18 -> 0.037 | F18: =Results_from_model!F18 -> 0.173 | G18: =Results_from_model!G18 -> -0.282 | H18: =Results_from_model!H18 -> -0.035 | I18: =Results_from_model!I18 -> -0.105 | J18: =Results_from_model!J18 -> -0.958 | K18: =Results_from_model!K18 -> 0.786
A19: =A18+0.25 -> 2028.5 | C19: =Results_from_model!C19 -> 0.3 | D19: =Results_from_model!D19 -> -0.284 | E19: =Results_from_model!E19 -> 0.11 | F19: =Results_from_model!F19 -> 0.21 | G19: =Results_from_model!G19 -> -0.297 | H19: =Results_from_model!H19 -> 0.036 | I19: =Results_from_model!I19 -> -0.064 | J19: =Results_from_model!J19 -> -0.941 | K19: =Results_from_model!K19 -> 0.86
A20: =A19+0.25 -> 2028.75 | C20: =Results_from_model!C20 -> 0.333 | D20: =Results_from_model!D20 -> -0.288 | E20: =Results_from_model!E20 -> 0.183 | F20: =Results_from_model!F20 -> 0.246 | G20: =Results_from_model!G20 -> -0.308 | H20: =Results_from_model!H20 -> 0.108 | I20: =Results_from_model!I20 -> -0.021 | J20: =Results_from_model!J20 -> -0.919 | K20: =Results_from_model!K20 -> 0.934
A21: =A20+0.25 -> 2029 | C21: =Results_from_model!C21 -> 0.366 | D21: =Results_from_model!D21 -> -0.288 | E21: =Results_from_model!E21 -> 0.257 | F21: =Results_from_model!F21 -> 0.283 | G21: =Results_from_model!G21 -> -0.314 | H21: =Results_from_model!H21 -> 0.18 | I21: =Results_from_model!I21 -> 0.024 | J21: =Results_from_model!J21 -> -0.892 | K21: =Results_from_model!K21 -> 1.007
A22: =A21+0.25 -> 2029.25 | C22: =Results_from_model!C22 -> 0.398 | D22: =Results_from_model!D22 -> -0.284 | E22: =Results_from_model!E22 -> 0.33 | F22: =Results_from_model!F22 -> 0.319 | G22: =Results_from_model!G22 -> -0.317 | H22: =Results_from_model!H22 -> 0.253 | I22: =Results_from_model!I22 -> 0.071 | J22: =Results_from_model!J22 -> -0.859 | K22: =Results_from_model!K22 -> 1.078
A23: =A22+0.25 -> 2029.5 | C23: =Results_from_model!C23 -> 0.429 | D23: =Results_from_model!D23 -> -0.277 | E23: =Results_from_model!E23 -> 0.403 | F23: =Results_from_model!F23 -> 0.355 | G23: =Results_from_model!G23 -> -0.315 | H23: =Results_from_model!H23 -> 0.326 | I23: =Results_from_model!I23 -> 0.119 | J23: =Results_from_model!J23 -> -0.821 | K23: =Results_from_model!K23 -> 1.147
A24: =A23+0.25 -> 2029.75 | C24: =Results_from_model!C24 -> 0.459 | D24: =Results_from_model!D24 -> -0.266 | E24: =Results_from_model!E24 -> 0.475 | F24: =Results_from_model!F24 -> 0.391 | G24: =Results_from_model!G24 -> -0.311 | H24: =Results_from_model!H24 -> 0.398 | I24: =Results_from_model!I24 -> 0.169 | J24: =Results_from_model!J24 -> -0.779 | K24: =Results_from_model!K24 -> 1.214
... A34: =A33+0.25 -> 2032.25 | C34: =Results_from_model!C34 -> 0.727 | D34: =Results_from_model!D34 -> -0.023 | E34: =Results_from_model!E34 -> 1.126 | F34: =Results_from_model!F34 -> 0.741 | G34: =Results_from_model!G34 -> -0.108 | H34: =Results_from_model!H34 -> 1.081 | I34: =Results_from_model!I34 -> 0.689 | J34: =Results_from_model!J34 -> -0.155 | K34: =Results_from_model!K34 -> 1.728
A35: =A34+0.25 -> 2032.5 | C35: =Results_from_model!C35 -> 0.75 | D35: =Results_from_model!D35 -> 0.012 | E35: =Results_from_model!E35 -> 1.183 | F35: =Results_from_model!F35 -> 0.775 | G35: =Results_from_model!G35 -> -0.075 | H35: =Results_from_model!H35 -> 1.145 | I35: =Results_from_model!I35 -> 0.742 | J35: =Results_from_model!J35 -> -0.074 | K35: =Results_from_model!K35 -> 1.761 | AD35: Figure 6C | AM35: Figure 6D
A36: =A35+0.25 -> 2032.75 | C36: =Results_from_model!C36 -> 0.774 | D36: =Results_from_model!D36 -> 0.048 | E36: =Results_from_model!E36 -> 1.24 | F36: =Results_from_model!F36 -> 0.81 | G36: =Results_from_model!G36 -> -0.04 | H36: =Results_from_model!H36 -> 1.207 | I36: =Results_from_model!I36 -> 0.795 | J36: =Results_from_model!J36 -> 0.01 | K36: =Results_from_model!K36 -> 1.788
A37: =A36+0.25 -> 2033 | C37: =Results_from_model!C37 -> 0.796 | D37: =Results_from_model!D37 -> 0.086 | E37: =Results_from_model!E37 -> 1.295 | F37: =Results_from_model!F37 -> 0.844 | G37: =Results_from_model!G37 -> -0.004 | H37: =Results_from_model!H37 -> 1.269 | I37: =Results_from_model!I37 -> 0.848 | J37: =Results_from_model!J37 -> 0.098 | K37: =Results_from_model!K37 -> 1.812
A38: =A37+0.25 -> 2033.25 | C38: =Results_from_model!C38 -> 0.818 | D38: =Results_from_model!D38 -> 0.125 | E38: =Results_from_model!E38 -> 1.349 | F38: =Results_from_model!F38 -> 0.878 | G38: =Results_from_model!G38 -> 0.034 | H38: =Results_from_model!H38 -> 1.33 | I38: =Results_from_model!I38 -> 0.901 | J38: =Results_from_model!J38 -> 0.19 | K38: =Results_from_model!K38 -> 1.83
A39: =A38+0.25 -> 2033.5 | C39: =Results_from_model!C39 -> 0.84 | D39: =Results_from_model!D39 -> 0.165 | E39: =Results_from_model!E39 -> 1.401 | F39: =Results_from_model!F39 -> 0.912 | G39: =Results_from_model!G39 -> 0.074 | H39: =Results_from_model!H39 -> 1.389 | I39: =Results_from_model!I39 -> 0.954 | J39: =Results_from_model!J39 -> 0.286 | K39: =Results_from_model!K39 -> 1.843
A40: =A39+0.25 -> 2033.75 | C40: =Results_from_model!C40 -> 0.861 | D40: =Results_from_model!D40 -> 0.206 | E40: =Results_from_model!E40 -> 1.453 | F40: =Results_from_model!F40 -> 0.946 | G40: =Results_from_model!G40 -> 0.115 | H40: =Results_from_model!H40 -> 1.448 | I40: =Results_from_model!I40 -> 1.006 | J40: =Results_from_model!J40 -> 0.386 | K40: =Results_from_model!K40 -> 1.851
A41: =A40+0.25 -> 2034 | C41: =Results_from_model!C41 -> 0.882 | D41: =Results_from_model!D41 -> 0.249 | E41: =Results_from_model!E41 -> 1.503 | F41: =Results_from_model!F41 -> 0.979 | G41: =Results_from_model!G41 -> 0.158 | H41: =Results_from_model!H41 -> 1.507 | I41: =Results_from_model!I41 -> 1.059 | J41: =Results_from_model!J41 -> 0.49 | K41: =Results_from_model!K41 -> 1.852
A42: =A41+0.25 -> 2034.25 | C42: =Results_from_model!C42 -> 0.903 | D42: =Results_from_model!D42 -> 0.292 | E42: =Results_from_model!E42 -> 1.552 | F42: =Results_from_model!F42 -> 1.013 | G42: =Results_from_model!G42 -> 0.202 | H42: =Results_from_model!H42 -> 1.564 | I42: =Results_from_model!I42 -> 1.111 | J42: =Results_from_model!J42 -> 0.599 | K42: =Results_from_model!K42 -> 1.847
A43: =A42+0.25 -> 2034.5 | C43: =Results_from_model!C43 -> 0.923 | D43: =Results_from_model!D43 -> 0.336 | E43: =Results_from_model!E43 -> 1.6 | F43: =Results_from_model!F43 -> 1.047 | G43: =Results_from_model!G43 -> 0.247 | H43: =Results_from_model!H43 -> 1.621 | I43: =Results_from_model!I43 -> 1.164 | J43: =Results_from_model!J43 -> 0.714 | K43: =Results_from_model!K43 -> 1.835 | T43: Human capital investment | U43: R&D spending | V43: Infrastructure investment
A44: =A43+0.25 -> 2034.75 | C44: =Results_from_model!C44 -> 0.942 | D44: =Results_from_model!D44 -> 0.381 | E44: =Results_from_model!E44 -> 1.647 | F44: =Results_from_model!F44 -> 1.08 | G44: =Results_from_model!G44 -> 0.293 | H44: =Results_from_model!H44 -> 1.676 | I44: =Results_from_model!I44 -> 1.216 | J44: =Results_from_model!J44 -> 0.835 | K44: =Results_from_model!K44 -> 1.816 | T44: =G105-D105 -> 0.657 | U44: =H105-E105 -> 0.919 | V44: =F105-C105 -> 1.382
A45: =A44+0.25 -> 2035 | C45: =Results_from_model!C45 -> 0.961 | D45: =Results_from_model!D45 -> 0.426 | E45: =Results_from_model!E45 -> 1.693 | F45: =Results_from_model!F45 -> 1.113 | G45: =Results_from_model!G45 -> 0.341 | H45: =Results_from_model!H45 -> 1.732 | I45: =Results_from_model!I45 -> 1.267 | J45: =Results_from_model!J45 -> 0.961 | K45: =Results_from_model!K45 -> 1.79
A46: =A45+0.25 -> 2035.25 | C46: =Results_from_model!C46 -> 0.98 | D46: =Results_from_model!D46 -> 0.472 | E46: =Results_from_model!E46 -> 1.738 | F46: =Results_from_model!F46 -> 1.147 | G46: =Results_from_model!G46 -> 0.389 | H46: =Results_from_model!H46 -> 1.786 | I46: =Results_from_model!I46 -> 1.319 | J46: =Results_from_model!J46 -> 1.094 | K46: =Results_from_model!K46 -> 1.758
A47: =A46+0.25 -> 2035.5 | C47: =Results_from_model!C47 -> 0.999 | D47: =Results_from_model!D47 -> 0.519 | E47: =Results_from_model!E47 -> 1.782 | F47: =Results_from_model!F47 -> 1.18 | G47: =Results_from_model!G47 -> 0.439 | H47: =Results_from_model!H47 -> 1.84 | I47: =Results_from_model!I47 -> 1.37 | J47: =Results_from_model!J47 -> 1.226 | K47: =Results_from_model!K47 -> 1.725
A48: =A47+0.25 -> 2035.75 | C48: =Results_from_model!C48 -> 1.017 | D48: =Results_from_model!D48 -> 0.566 | E48: =Results_from_model!E48 -> 1.825 | F48: =Results_from_model!F48 -> 1.213 | G48: =Results_from_model!G48 -> 0.489 | H48: =Results_from_model!H48 -> 1.893 | I48: =Results_from_model!I48 -> 1.421 | J48: =Results_from_model!J48 -> 1.355 | K48: =Results_from_model!K48 -> 1.693
A49: =A48+0.25 -> 2036 | C49: =Results_from_model!C49 -> 1.035 | D49: =Results_from_model!D49 -> 0.614 | E49: =Results_from_model!E49 -> 1.866 | F49: =Results_from_model!F49 -> 1.246 | G49: =Results_from_model!G49 -> 0.54 | H49: =Results_from_model!H49 -> 1.945 | I49: =Results_from_model!I49 -> 1.472 | J49: =Results_from_model!J49 -> 1.482 | K49: =Results_from_model!K49 -> 1.662
A50: =A49+0.25 -> 2036.25 | C50: =Results_from_model!C50 -> 1.052 | D50: =Results_from_model!D50 -> 0.662 | E50: =Results_from_model!E50 -> 1.907 | F50: =Results_from_model!F50 -> 1.279 | G50: =Results_from_model!G50 -> 0.592 | H50: =Results_from_model!H50 -> 1.996 | I50: =Results_from_model!I50 -> 1.523 | J50: =Results_from_model!J50 -> 1.606 | K50: =Results_from_model!K50 -> 1.634
A51: =A50+0.25 -> 2036.5 | C51: =Results_from_model!C51 -> 1.069 | D51: =Results_from_model!D51 -> 0.711 | E51: =Results_from_model!E51 -> 1.948 | F51: =Results_from_model!F51 -> 1.312 | G51: =Results_from_model!G51 -> 0.645 | H51: =Results_from_model!H51 -> 2.047 | I51: =Results_from_model!I51 -> 1.573 | J51: =Results_from_model!J51 -> 1.727 | K51: =Results_from_model!K51 -> 1.607
A52: =A51+0.25 -> 2036.75 | C52: =Results_from_model!C52 -> 1.086 | D52: =Results_from_model!D52 -> 0.76 | E52: =Results_from_model!E52 -> 1.987 | F52: =Results_from_model!F52 -> 1.345 | G52: =Results_from_model!G52 -> 0.699 | H52: =Results_from_model!H52 -> 2.098 | I52: =Results_from_model!I52 -> 1.623 | J52: =Results_from_model!J52 -> 1.846 | K52: =Results_from_model!K52 -> 1.581
...

Sheet Not_used_Results_from_model_OLD
A1: 1 | B1: 2 | C1: 3 | D1: 4 | E1: 5 | F1: 6 | G1: 7 | H1: 8 | I1: 9 | N1: 2 | O1: 3 | P1: 4 | Q1: 5 | R1: 6 | S1: 7 | T1: 8 | U1: 9 | V1: 10 | W1: 11 | X1: 12 | Y1: 13
A2: AE | B2: Variables -> | C2: Model_HumanCapital_epsi_ig___yd | D2: Model_HumanCapital_epsi_cge___yd | E2: Model_HumanCapital_epsi_cgrd___yd | F2: Model_HumanCapital_epsi_igeff10y___yd | G2: Model_HumanCapital_epsi_cgeeff10y___yd | H2: Model_HumanCapital_epsi_cgrd_eff__yd | I2: Model_HumanCapital_epsi_cgeCgrd__yd | J2: Model_HumanCapital_epsi_cgeCgrd_advt__yd | K2: Model_HumanCapital_epsi_cgeCgrd_limt__yd | M2: EMDE | N2: EM_Model_HumanCapital_epsiig___yd | O2: EM_Model_HumanCapital_epsicge___yd | P2: EM_Model_HumanCapital_epsiigeff10y___yd | Q2: EM_Model_HumanCapital_epsicgeeff10y___yd | R2: EM_Model_HumanCapital_epsiigeff25y___yd | S2: EM_Model_HumanCapital_epsicgeeff25y___yd | T2: EM_Model_HumanCapital_epsiiglow__yd | U2: EM_Model_HumanCapital_epsicgelow__yd | V2: EM_Model_HumanCapital_epsiigeff10ylow__yd | W2: EM_Model_HumanCapital_epsicgeeff10ylow__yd | X2: EM_Model_HumanCapital_epsiigeff25ylow__yd | Y2: EM_Model_HumanCapital_epsicgeeff25ylow__yd
B3: Comments ->
B4: Class[Size] -> | C4: Series[201-by-1] | D4: Series[201-by-1] | E4: Series[201-by-1] | F4: Series[201-by-1] | G4: Series[201-by-1] | I4: Series[2002-by-1] | N4: Series[201-by-1] | O4: Series[201-by-1] | P4: Series[201-by-1] | Q4: Series[201-by-1] | R4: Series[201-by-1] | S4: Series[201-by-1]
A9: 2026 | C9: =HLOOKUP(C2,#REF!,6,FALSE) -> #REF! | D9: -0.175 | E9: -0.369 | F9: -0.177 | G9: -0.189 | H9: -0.42654873 | I9: -0.315 | J9: -0.78191876 | K9: 0.14670952 | N9: -0.075 | O9: 0.182 | P9: -0.272 | Q9: 0.492 | R9: -0.15 | S9: 0.362
A10: =A9+0.25 -> 2026.25 | C10: -0.075 | D10: -0.201 | E10: -0.376 | F10: -0.122 | G10: -0.22 | H10: -0.44013753 | I10: -0.332 | J10: -0.85200773 | K10: 0.18475969 | N10: 0.046 | O10: 0.093 | P10: -0.158 | Q10: 0.372 | R10: -0.034 | S10: 0.259
A11: =A10+0.25 -> 2026.5 | C11: -0.02 | D11: -0.224 | E11: -0.364 | F11: -0.067 | G11: -0.248 | H11: -0.43523672 | I11: -0.336 | J11: -0.90709675 | K11: 0.23651489 | N11: 0.165 | O11: 0.014 | P11: -0.04 | Q11: 0.26 | R11: 0.083 | S11: 0.165
A12: =A11+0.25 -> 2026.75 | C12: 0.034 | D12: -0.243 | E12: -0.337 | F12: -0.014 | G12: -0.273 | H12: -0.41487159 | I12: -0.328 | J12: -0.94757748 | K12: 0.29705413 | N12: 0.282 | O12: -0.054 | P12: 0.078 | Q12: 0.157 | R12: 0.199 | S12: 0.081
A13: =A12+0.25 -> 2027 | C13: 0.087 | D13: -0.259 | E13: -0.298 | F13: 0.039 | G13: -0.295 | H13: -0.38216391 | I13: -0.312 | J13: -0.9750975 | K13: 0.36350619 | N13: 0.396 | O13: -0.11 | P13: 0.197 | Q13: 0.066 | R13: 0.313 | S13: 0.01
A14: =A13+0.25 -> 2027.25 | C14: 0.138 | D14: -0.272 | E14: -0.25 | F14: 0.09 | G14: -0.313 | H14: -0.33979807 | I14: -0.287 | J14: -0.99201143 | K14: 0.43460707 | N14: 0.506 | O14: -0.155 | P14: 0.316 | Q14: -0.014 | R14: 0.425 | S14: -0.051
A15: =A14+0.25 -> 2027.5 | C15: 0.188 | D15: -0.281 | E15: -0.196 | F15: 0.141 | G15: -0.327 | H15: -0.28995539 | I15: -0.257 | J15: -0.99986603 | K15: 0.50888041 | N15: 0.612 | O15: -0.189 | P15: 0.436 | Q15: -0.083 | R15: 0.534 | S15: -0.101
A16: =A15+0.25 -> 2027.75 | C16: 0.236 | D16: -0.287 | E16: -0.136 | F16: 0.19 | G16: -0.338 | H16: -0.23437239 | I16: -0.222 | J16: -0.99918492 | K16: 0.58433302 | N16: 0.716 | O16: -0.213 | P16: 0.555 | Q16: -0.142 | R16: 0.642 | S16: -0.141
A17: =A16+0.25 -> 2028 | C17: 0.283 | D17: -0.289 | E17: -0.072 | F17: 0.239 | G17: -0.346 | H17: -0.17442063 | I17: -0.184 | J17: -0.99084891 | K17: 0.6599488 | N17: 0.816 | O17: -0.228 | P17: 0.674 | Q17: -0.19 | R17: 0.748 | S17: -0.172
A18: =A17+0.25 -> 2028.25 | C18: 0.329 | D18: -0.289 | E18: -0.006 | F18: 0.286 | G18: -0.35 | H18: -0.11117975 | I18: -0.142 | J18: -0.97633782 | K18: 0.73579093 | N18: 0.913 | O18: -0.233 | P18: 0.792 | Q18: -0.228 | R18: 0.852 | S18: -0.192
A19: =A18+0.25 -> 2028.5 | C19: 0.374 | D19: -0.286 | E19: 0.061 | F19: 0.333 | G19: -0.352 | H19: -0.045498186 | I19: -0.098 | J19: -0.95640724 | K19: 0.81138165 | N19: 1.007 | O19: -0.231 | P19: 0.911 | Q19: -0.257 | R19: 0.954 | S19: -0.205
A20: =A19+0.25 -> 2028.75 | C20: 0.417 | D20: -0.28 | E20: 0.13 | F20: 0.379 | G20: -0.351 | H20: 0.021958332 | I20: -0.052 | J20: -0.93093781 | K20: 0.88554596 | N20: 1.098 | O20: -0.221 | P20: 1.029 | Q20: -0.276 | R20: 1.054 | S20: -0.208
A21: =A20+0.25 -> 2029 | C21: 0.459 | D21: -0.272 | E21: 0.199 | F21: 0.424 | G21: -0.346 | H21: 0.090668181 | I21: -0.005 | J21: -0.90087384 | K21: 0.95848518 | N21: 1.186 | O21: -0.204 | P21: 1.147 | Q21: -0.286 | R21: 1.152 | S21: -0.204
... A105: =A104+0.25 -> 2050 | C105: 2.155 | D105: 3.285 | E105: 3.211 | F105: 2.63 | G105: 4.141 | H105: 4.1821142 | I105: 3.699 | J105: 5.6944956 | K105: 1.2409603 | N105: 3.746 | O105: 5.464 | P105: 7.147 | Q105: 10.387 | R105: 6.147 | S105: 7.872
C108: =C105-Results_from_model!C105 -> 0.515 | D108: =D105-Results_from_model!D105 -> 0.127 | E108: =E105-Results_from_model!E105 -> 0.016 | F108: =F105-Results_from_model!F105 -> -0.392 | G108: =G105-Results_from_model!G105 -> 0.326 | H108: =H105-Results_from_model!H105 -> 0.068114225 | I108: =I105-Results_from_model!I105 -> 0.009 | J108: =J105-Results_from_model!J105 -> 0.087495561 | ... S108: =S105-Results_from_model!S105 -> -0.113

Sheet Annex_Joint_EM
A1: 1
B2: Variables -> | C2: EM_Model_HumanCapital_epsiig___yd | D2: EM_Model_HumanCapital_epsicge___yd | E2: EM_Model_HumanCapital_epsiigCge___yd | F2: EM_Model_HumanCapital_epsiigCgeVarShare___yd
B3: Comments ->
B4: Class[Size] -> | C4: Series[201-by-1] | D4: Series[201-by-1] | E4: Series[201-by-1] | F4: Series[201-by-1]
B5: 0Q4
B6: 1Q1
B7: 1Q2 | K7: Infrastructure investment | L7: Human capital investment | M7: Human capital investment+Infrastructure investment
B8: 1Q3 | J8: 2026 | K8: =VLOOKUP(J8,A:F,3,FALSE) -> -0.063 | L8: =VLOOKUP(J8,A:F,4,FALSE) -> 0.177 | M8: =VLOOKUP(J8,A:F,5,FALSE) -> 0.087 | N8: =VLOOKUP(J8,A:F,6,FALSE) -> 0.116
A9: 2026 | B9: 1Q4 | C9: =HLOOKUP(C$2,Models_Results!$B:$AAS,$H9,FALSE) -> -0.063 | D9: =HLOOKUP(D$2,Models_Results!$B:$AAS,$H9,FALSE) -> 0.177 | E9: =HLOOKUP(E$2,Models_Results!$B:$AAS,$H9,FALSE) -> 0.087 | F9: =HLOOKUP(F$2,Models_Results!$B:$AAS,$H9,FALSE) -> 0.116 | H9: 6 | J9: 2027 | K9: =VLOOKUP(J9,A:F,3,FALSE) -> 0.387 | L9: =VLOOKUP(J9,A:F,4,FALSE) -> -0.125 | M9: =VLOOKUP(J9,A:F,5,FALSE) -> 0.154 | N9: =VLOOKUP(J9,A:F,6,FALSE) -> 0.184
A10: =A9+0.25 -> 2026.25 | B10: 2Q1 | C10: =HLOOKUP(C$2,Models_Results!$B:$AAS,$H10,FALSE) -> 0.052 | D10: =HLOOKUP(D$2,Models_Results!$B:$AAS,$H10,FALSE) -> 0.082 | E10: =HLOOKUP(E$2,Models_Results!$B:$AAS,$H10,FALSE) -> 0.096 | F10: =HLOOKUP(F$2,Models_Results!$B:$AAS,$H10,FALSE) -> 0.125 | H10: 7 | J10: 2028 | K10: =VLOOKUP(J10,A:F,3,FALSE) -> 0.791 | L10: =VLOOKUP(J10,A:F,4,FALSE) -> -0.233 | M10: =VLOOKUP(J10,A:F,5,FALSE) -> 0.295 | N10: =VLOOKUP(J10,A:F,6,FALSE) -> 0.327
A11: =A10+0.25 -> 2026.5 | B11: 2Q2 | C11: =HLOOKUP(C$2,Models_Results!$B:$AAS,$H11,FALSE) -> 0.166 | D11: =HLOOKUP(D$2,Models_Results!$B:$AAS,$H11,FALSE) -> 0 | E11: =HLOOKUP(E$2,Models_Results!$B:$AAS,$H11,FALSE) -> 0.11 | F11: =HLOOKUP(F$2,Models_Results!$B:$AAS,$H11,FALSE) -> 0.139 | H11: 8 | J11: 2029 | K11: =VLOOKUP(J11,A:F,3,FALSE) -> 1.15 | L11: =VLOOKUP(J11,A:F,4,FALSE) -> -0.187 | M11: =VLOOKUP(J11,A:F,5,FALSE) -> 0.492 | N11: =VLOOKUP(J11,A:F,6,FALSE) -> 0.526
A12: =A11+0.25 -> 2026.75 | B12: 2Q3 | C12: =HLOOKUP(C$2,Models_Results!$B:$AAS,$H12,FALSE) -> 0.278 | D12: =HLOOKUP(D$2,Models_Results!$B:$AAS,$H12,FALSE) -> -0.069 | E12: =HLOOKUP(E$2,Models_Results!$B:$AAS,$H12,FALSE) -> 0.129 | F12: =HLOOKUP(F$2,Models_Results!$B:$AAS,$H12,FALSE) -> 0.159 | H12: 9 | J12: 2030 | K12: =VLOOKUP(J12,A:F,3,FALSE) -> 1.468 | L12: =VLOOKUP(J12,A:F,4,FALSE) -> -0.028 | M12: =VLOOKUP(J12,A:F,5,FALSE) -> 0.728 | N12: =VLOOKUP(J12,A:F,6,FALSE) -> 0.765
A13: =A12+0.25 -> 2027 | B13: 2Q4 | C13: =HLOOKUP(C$2,Models_Results!$B:$AAS,$H13,FALSE) -> 0.387 | D13: =HLOOKUP(D$2,Models_Results!$B:$AAS,$H13,FALSE) -> -0.125 | E13: =HLOOKUP(E$2,Models_Results!$B:$AAS,$H13,FALSE) -> 0.154 | F13: =HLOOKUP(F$2,Models_Results!$B:$AAS,$H13,FALSE) -> 0.184 | H13: 10 | J13: 2031 | K13: =VLOOKUP(J13,A:F,3,FALSE) -> 1.749 | L13: =VLOOKUP(J13,A:F,4,FALSE) -> 0.212 | M13: =VLOOKUP(J13,A:F,5,FALSE) -> 0.99 | N13: =VLOOKUP(J13,A:F,6,FALSE) -> 1.031
A14: =A13+0.25 -> 2027.25 | B14: 3Q1 | C14: =HLOOKUP(C$2,Models_Results!$B:$AAS,$H14,FALSE) -> 0.493 | D14: =HLOOKUP(D$2,Models_Results!$B:$AAS,$H14,FALSE) -> -0.169 | E14: =HLOOKUP(E$2,Models_Results!$B:$AAS,$H14,FALSE) -> 0.183 | F14: =HLOOKUP(F$2,Models_Results!$B:$AAS,$H14,FALSE) -> 0.213 | H14: 11 | J14: 2032 | K14: =VLOOKUP(J14,A:F,3,FALSE) -> 1.998 | L14: =VLOOKUP(J14,A:F,4,FALSE) -> 0.509 | M14: =VLOOKUP(J14,A:F,5,FALSE) -> 1.267 | N14: =VLOOKUP(J14,A:F,6,FALSE) -> 1.315
A15: =A14+0.25 -> 2027.5 | B15: 3Q2 | C15: =HLOOKUP(C$2,Models_Results!$B:$AAS,$H15,FALSE) -> 0.595 | D15: =HLOOKUP(D$2,Models_Results!$B:$AAS,$H15,FALSE) -> -0.201 | E15: =HLOOKUP(E$2,Models_Results!$B:$AAS,$H15,FALSE) -> 0.217 | F15: =HLOOKUP(F$2,Models_Results!$B:$AAS,$H15,FALSE) -> 0.247 | H15: 12 | J15: 2033 | K15: =VLOOKUP(J15,A:F,3,FALSE) -> 2.218 | L15: =VLOOKUP(J15,A:F,4,FALSE) -> 0.843 | M15: =VLOOKUP(J15,A:F,5,FALSE) -> 1.553 | N15: =VLOOKUP(J15,A:F,6,FALSE) -> 1.61
A16: =A15+0.25 -> 2027.75 | B16: 3Q3 | C16: =HLOOKUP(C$2,Models_Results!$B:$AAS,$H16,FALSE) -> 0.695 | D16: =HLOOKUP(D$2,Models_Results!$B:$AAS,$H16,FALSE) -> -0.222 | E16: =HLOOKUP(E$2,Models_Results!$B:$AAS,$H16,FALSE) -> 0.254 | F16: =HLOOKUP(F$2,Models_Results!$B:$AAS,$H16,FALSE) -> 0.285 | H16: 13 | J16: 2034 | K16: =VLOOKUP(J16,A:F,3,FALSE) -> 2.413 | L16: =VLOOKUP(J16,A:F,4,FALSE) -> 1.199 | M16: =VLOOKUP(J16,A:F,5,FALSE) -> 1.84 | N16: =VLOOKUP(J16,A:F,6,FALSE) -> 1.909
A17: =A16+0.25 -> 2028 | B17: 3Q4 | C17: =HLOOKUP(C$2,Models_Results!$B:$AAS,$H17,FALSE) -> 0.791 | D17: =HLOOKUP(D$2,Models_Results!$B:$AAS,$H17,FALSE) -> -0.233 | E17: =HLOOKUP(E$2,Models_Results!$B:$AAS,$H17,FALSE) -> 0.295 | F17: =HLOOKUP(F$2,Models_Results!$B:$AAS,$H17,FALSE) -> 0.327 | H17: 14 | J17: 2035 | K17: =VLOOKUP(J17,A:F,3,FALSE) -> 2.584 | L17: =VLOOKUP(J17,A:F,4,FALSE) -> 1.567 | M17: =VLOOKUP(J17,A:F,5,FALSE) -> 2.124 | N17: =VLOOKUP(J17,A:F,6,FALSE) -> 2.208
A18: =A17+0.25 -> 2028.25 | B18: 4Q1 | C18: =HLOOKUP(C$2,Models_Results!$B:$AAS,$H18,FALSE) -> 0.885 | D18: =HLOOKUP(D$2,Models_Results!$B:$AAS,$H18,FALSE) -> -0.234 | E18: =HLOOKUP(E$2,Models_Results!$B:$AAS,$H18,FALSE) -> 0.34 | F18: =HLOOKUP(F$2,Models_Results!$B:$AAS,$H18,FALSE) -> 0.372 | H18: 15 | J18: 2036 | K18: =VLOOKUP(J18,A:F,3,FALSE) -> 2.736 | L18: =VLOOKUP(J18,A:F,4,FALSE) -> 1.936 | M18: =VLOOKUP(J18,A:F,5,FALSE) -> 2.4 | N18: =VLOOKUP(J18,A:F,6,FALSE) -> 2.477
A19: =A18+0.25 -> 2028.5 | B19: 4Q2 | C19: =HLOOKUP(C$2,Models_Results!$B:$AAS,$H19,FALSE) -> 0.976 | D19: =HLOOKUP(D$2,Models_Results!$B:$AAS,$H19,FALSE) -> -0.226 | E19: =HLOOKUP(E$2,Models_Results!$B:$AAS,$H19,FALSE) -> 0.388 | F19: =HLOOKUP(F$2,Models_Results!$B:$AAS,$H19,FALSE) -> 0.42 | H19: 16 | J19: 2037 | K19: =VLOOKUP(J19,A:F,3,FALSE) -> 2.87 | L19: =VLOOKUP(J19,A:F,4,FALSE) -> 2.302 | M19: =VLOOKUP(J19,A:F,5,FALSE) -> 2.668 | N19: =VLOOKUP(J19,A:F,6,FALSE) -> 2.671
A20: =A19+0.25 -> 2028.75 | B20: 4Q3 | C20: =HLOOKUP(C$2,Models_Results!$B:$AAS,$H20,FALSE) -> 1.064 | D20: =HLOOKUP(D$2,Models_Results!$B:$AAS,$H20,FALSE) -> -0.21 | E20: =HLOOKUP(E$2,Models_Results!$B:$AAS,$H20,FALSE) -> 0.439 | F20: =HLOOKUP(F$2,Models_Results!$B:$AAS,$H20,FALSE) -> 0.472 | H20: 17 | J20: 2038 | K20: =VLOOKUP(J20,A:F,3,FALSE) -> 2.988 | L20: =VLOOKUP(J20,A:F,4,FALSE) -> 2.659 | M20: =VLOOKUP(J20,A:F,5,FALSE) -> 2.924 | N20: =VLOOKUP(J20,A:F,6,FALSE) -> 2.807
A21: =A20+0.25 -> 2029 | B21: 4Q4 | C21: =HLOOKUP(C$2,Models_Results!$B:$AAS,$H21,FALSE) -> 1.15 | D21: =HLOOKUP(D$2,Models_Results!$B:$AAS,$H21,FALSE) -> -0.187 | E21: =HLOOKUP(E$2,Models_Results!$B:$AAS,$H21,FALSE) -> 0.492 | F21: =HLOOKUP(F$2,Models_Results!$B:$AAS,$H21,FALSE) -> 0.526 | H21: 18 | J21: 2039 | K21: =VLOOKUP(J21,A:F,3,FALSE) -> 3.091 | L21: =VLOOKUP(J21,A:F,4,FALSE) -> 3.003 | M21: =VLOOKUP(J21,A:F,5,FALSE) -> 3.168 | N21: =VLOOKUP(J21,A:F,6,FALSE) -> 2.95
... A32: =A31+0.25 -> 2031.75 | B32: 7Q3 | C32: =HLOOKUP(C$2,Models_Results!$B:$AAS,$H32,FALSE) -> 1.938 | D32: =HLOOKUP(D$2,Models_Results!$B:$AAS,$H32,FALSE) -> 0.43 | E32: =HLOOKUP(E$2,Models_Results!$B:$AAS,$H32,FALSE) -> 1.197 | F32: =HLOOKUP(F$2,Models_Results!$B:$AAS,$H32,FALSE) -> 1.243 | H32: 29 | J32: 2050 | K32: =VLOOKUP(J32,A:F,3,FALSE) -> 3.666 | L32: =VLOOKUP(J32,A:F,4,FALSE) -> 5.698 | M32: =VLOOKUP(J32,A:F,5,FALSE) -> 4.989 | N32: =VLOOKUP(J32,A:F,6,FALSE) -> 4.886
A33: =A32+0.25 -> 2032 | B33: 7Q4 | C33: =HLOOKUP(C$2,Models_Results!$B:$AAS,$H33,FALSE) -> 1.998 | D33: =HLOOKUP(D$2,Models_Results!$B:$AAS,$H33,FALSE) -> 0.509 | E33: =HLOOKUP(E$2,Models_Results!$B:$AAS,$H33,FALSE) -> 1.267 | F33: =HLOOKUP(F$2,Models_Results!$B:$AAS,$H33,FALSE) -> 1.315 | H33: 30
A34: =A33+0.25 -> 2032.25 | B34: 8Q1 | C34: =HLOOKUP(C$2,Models_Results!$B:$AAS,$H34,FALSE) -> 2.056 | D34: =HLOOKUP(D$2,Models_Results!$B:$AAS,$H34,FALSE) -> 0.589 | E34: =HLOOKUP(E$2,Models_Results!$B:$AAS,$H34,FALSE) -> 1.338 | F34: =HLOOKUP(F$2,Models_Results!$B:$AAS,$H34,FALSE) -> 1.388 | H34: 31
A35: =A34+0.25 -> 2032.5 | B35: 8Q2 | C35: =HLOOKUP(C$2,Models_Results!$B:$AAS,$H35,FALSE) -> 2.111 | D35: =HLOOKUP(D$2,Models_Results!$B:$AAS,$H35,FALSE) -> 0.672 | E35: =HLOOKUP(E$2,Models_Results!$B:$AAS,$H35,FALSE) -> 1.41 | F35: =HLOOKUP(F$2,Models_Results!$B:$AAS,$H35,FALSE) -> 1.462 | H35: 32
A36: =A35+0.25 -> 2032.75 | B36: 8Q3 | C36: =HLOOKUP(C$2,Models_Results!$B:$AAS,$H36,FALSE) -> 2.166 | D36: =HLOOKUP(D$2,Models_Results!$B:$AAS,$H36,FALSE) -> 0.757 | E36: =HLOOKUP(E$2,Models_Results!$B:$AAS,$H36,FALSE) -> 1.481 | F36: =HLOOKUP(F$2,Models_Results!$B:$AAS,$H36,FALSE) -> 1.535 | H36: 33
A37: =A36+0.25 -> 2033 | B37: 8Q4 | C37: =HLOOKUP(C$2,Models_Results!$B:$AAS,$H37,FALSE) -> 2.218 | D37: =HLOOKUP(D$2,Models_Results!$B:$AAS,$H37,FALSE) -> 0.843 | E37: =HLOOKUP(E$2,Models_Results!$B:$AAS,$H37,FALSE) -> 1.553 | F37: =HLOOKUP(F$2,Models_Results!$B:$AAS,$H37,FALSE) -> 1.61 | H37: 34
A38: =A37+0.25 -> 2033.25 | B38: 9Q1 | C38: =HLOOKUP(C$2,Models_Results!$B:$AAS,$H38,FALSE) -> 2.269 | D38: =HLOOKUP(D$2,Models_Results!$B:$AAS,$H38,FALSE) -> 0.93 | E38: =HLOOKUP(E$2,Models_Results!$B:$AAS,$H38,FALSE) -> 1.625 | F38: =HLOOKUP(F$2,Models_Results!$B:$AAS,$H38,FALSE) -> 1.684 | H38: 35
A39: =A38+0.25 -> 2033.5 | B39: 9Q2 | C39: =HLOOKUP(C$2,Models_Results!$B:$AAS,$H39,FALSE) -> 2.318 | D39: =HLOOKUP(D$2,Models_Results!$B:$AAS,$H39,FALSE) -> 1.019 | E39: =HLOOKUP(E$2,Models_Results!$B:$AAS,$H39,FALSE) -> 1.696 | F39: =HLOOKUP(F$2,Models_Results!$B:$AAS,$H39,FALSE) -> 1.759 | H39: 36
A40: =A39+0.25 -> 2033.75 | B40: 9Q3 | C40: =HLOOKUP(C$2,Models_Results!$B:$AAS,$H40,FALSE) -> 2.366 | D40: =HLOOKUP(D$2,Models_Results!$B:$AAS,$H40,FALSE) -> 1.109 | E40: =HLOOKUP(E$2,Models_Results!$B:$AAS,$H40,FALSE) -> 1.768 | F40: =HLOOKUP(F$2,Models_Results!$B:$AAS,$H40,FALSE) -> 1.834 | H40: 37
A41: =A40+0.25 -> 2034 | B41: 9Q4 | C41: =HLOOKUP(C$2,Models_Results!$B:$AAS,$H41,FALSE) -> 2.413 | D41: =HLOOKUP(D$2,Models_Results!$B:$AAS,$H41,FALSE) -> 1.199 | E41: =HLOOKUP(E$2,Models_Results!$B:$AAS,$H41,FALSE) -> 1.84 | F41: =HLOOKUP(F$2,Models_Results!$B:$AAS,$H41,FALSE) -> 1.909 | H41: 38
A42: =A41+0.25 -> 2034.25 | B42: 10Q1 | C42: =HLOOKUP(C$2,Models_Results!$B:$AAS,$H42,FALSE) -> 2.458 | D42: =HLOOKUP(D$2,Models_Results!$B:$AAS,$H42,FALSE) -> 1.29 | E42: =HLOOKUP(E$2,Models_Results!$B:$AAS,$H42,FALSE) -> 1.911 | F42: =HLOOKUP(F$2,Models_Results!$B:$AAS,$H42,FALSE) -> 1.984 | H42: 39
A43: =A42+0.25 -> 2034.5 | B43: 10Q2 | C43: =HLOOKUP(C$2,Models_Results!$B:$AAS,$H43,FALSE) -> 2.501 | D43: =HLOOKUP(D$2,Models_Results!$B:$AAS,$H43,FALSE) -> 1.382 | E43: =HLOOKUP(E$2,Models_Results!$B:$AAS,$H43,FALSE) -> 1.982 | F43: =HLOOKUP(F$2,Models_Results!$B:$AAS,$H43,FALSE) -> 2.059 | H43: 40
A44: =A43+0.25 -> 2034.75 | B44: 10Q3 | C44: =HLOOKUP(C$2,Models_Results!$B:$AAS,$H44,FALSE) -> 2.543 | D44: =HLOOKUP(D$2,Models_Results!$B:$AAS,$H44,FALSE) -> 1.474 | E44: =HLOOKUP(E$2,Models_Results!$B:$AAS,$H44,FALSE) -> 2.053 | F44: =HLOOKUP(F$2,Models_Results!$B:$AAS,$H44,FALSE) -> 2.134 | H44: 41
... A105: =A104+0.25 -> 2050 | B105: 25Q4 | C105: =HLOOKUP(C$2,Models_Results!$B:$AAS,$H105,FALSE) -> 3.666 | D105: =HLOOKUP(D$2,Models_Results!$B:$AAS,$H105,FALSE) -> 5.698 | E105: =HLOOKUP(E$2,Models_Results!$B:$AAS,$H105,FALSE) -> 4.989 | F105: =HLOOKUP(F$2,Models_Results!$B:$AAS,$H105,FALSE) -> 4.886 | H105: 102
B106: 26Q1 | C106: =HLOOKUP(C$2,Models_Results!$B:$AAS,$H106,FALSE) -> 3.672 | D106: =HLOOKUP(D$2,Models_Results!$B:$AAS,$H106,FALSE) -> 5.737 | E106: =HLOOKUP(E$2,Models_Results!$B:$AAS,$H106,FALSE) -> 5.015 | F106: =HLOOKUP(F$2,Models_Results!$B:$AAS,$H106,FALSE) -> 4.923 | H106: 103
B107: 26Q2 | C107: =HLOOKUP(C$2,Models_Results!$B:$AAS,$H107,FALSE) -> 3.678 | D107: =HLOOKUP(D$2,Models_Results!$B:$AAS,$H107,FALSE) -> 5.775 | E107: =HLOOKUP(E$2,Models_Results!$B:$AAS,$H107,FALSE) -> 5.04 | F107: =HLOOKUP(F$2,Models_Results!$B:$AAS,$H107,FALSE) -> 4.959 | H107: 104
B108: 26Q3 | C108: =HLOOKUP(C$2,Models_Results!$B:$AAS,$H108,FALSE) -> 3.683 | D108: =HLOOKUP(D$2,Models_Results!$B:$AAS,$H108,FALSE) -> 5.812 | E108: =HLOOKUP(E$2,Models_Results!$B:$AAS,$H108,FALSE) -> 5.064 | F108: =HLOOKUP(F$2,Models_Results!$B:$AAS,$H108,FALSE) -> 4.994 | H108: 105
B109: 26Q4 | C109: =HLOOKUP(C$2,Models_Results!$B:$AAS,$H109,FALSE) -> 3.688 | D109: =HLOOKUP(D$2,Models_Results!$B:$AAS,$H109,FALSE) -> 5.848 | E109: =HLOOKUP(E$2,Models_Results!$B:$AAS,$H109,FALSE) -> 5.088 | F109: =HLOOKUP(F$2,Models_Results!$B:$AAS,$H109,FALSE) -> 5.029 | H109: 106
B110: 27Q1 | C110: =HLOOKUP(C$2,Models_Results!$B:$AAS,$H110,FALSE) -> 3.693 | D110: =HLOOKUP(D$2,Models_Results!$B:$AAS,$H110,FALSE) -> 5.884 | E110: =HLOOKUP(E$2,Models_Results!$B:$AAS,$H110,FALSE) -> 5.111 | F110: =HLOOKUP(F$2,Models_Results!$B:$AAS,$H110,FALSE) -> 5.064 | H110: 107
...

Sheet Annex_Figure2
A1: 1 | B1: 2 | C1: 3 | D1: 4 | E1: 5 | F1: 6 | G1: 7 | H1: 8 | I1: 9 | J1: 10 | K1: 11 | L1: 12 | M1: 13 | N1: 14 | O1: 15 | AD1: 6 | AG1: 2 | AJ1: 14 | AK1: 15 | AL1: 6
A2: Variables -> | B2: =Results_from_model!N2 -> EM_Model_HumanCapital_epsiig___yd | C2: =Results_from_model!O2 -> EM_Model_HumanCapital_epsicge___yd | D2: =Results_from_model!P2 -> EM_Model_HumanCapital_epsiigeff30y___yd | E2: =Results_from_model!Q2 -> EM_Model_HumanCapital_epsicgeeff30y___yd | F2: =Results_from_model!R2 -> EM_Model_HumanCapital_epsiigeff25y___yd | G2: =Results_from_model!S2 -> EM_Model_HumanCapital_epsicgeeff25y___yd | H2: =Results_from_model!T2 -> EM_Model_HumanCapital_epsiiglow___yd | I2: =Results_from_model!U2 -> EM_Model_HumanCapital_epsicgelow___yd | J2: EM_Model_HumanCapital_epsiigeff15ylow___yd | K2: EM_Model_HumanCapital_epsicgeeff15ylow___yd | L2: =Results_from_model!X2 -> EM_Model_HumanCapital_epsiigeff25ylow___yd | M2: =Results_from_model!Y2 -> EM_Model_HumanCapital_epsicgeeff25ylow___yd | N2: =Results_from_model!Z2 -> EM_Model_HumanCapital_epsiigeff25y_al___yd | O2: =Results_from_model!AA2 -> EM_Model_HumanCapital_epsicgeeff25y_al___yd | AD2: EM_Model_HumanCapital_epsiigeff25y___yd | AG2: EM_Model_HumanCapital_epsiig___yd | AJ2: EM_Model_HumanCapital_epsiigeff25y_al___yd | AK2: EM_Model_HumanCapital_epsicgeeff25y_al___yd | AL2: EM_Model_HumanCapital_epsiigeff25y___yd
A3: Comments ->
A4: Class[Size] -> | B4: Series[201-by-1] | C4: Series[201-by-1] | D4: Series[201-by-1] | E4: Series[201-by-1] | F4: Series[201-by-1] | G4: Series[201-by-1] | AD4: Series[201-by-1] | AG4: Series[201-by-1] | AL4: Series[201-by-1]
AC5: 0 | AF5: 0 | AI5: 0 | AO5: 0 | AP5: 0 | AQ5: 0
AC6: 0.058637732 | AF6: -0.74619317 | AI6: 0.27276259 | AO6: 0.34985225 | AP6: 0.058637732 | AQ6: 0.16478001
AC7: -0.45513589 | AF7: -0.26584627 | AI7: -0.42869065 | AO7: -0.42515368 | AP7: -0.45513589 | AQ7: -0.44180603
AC8: -0.39125716 | AF8: -0.17377025 | AI8: -0.38240962 | AO8: -0.3840147 | AP8: -0.39125716 | AQ8: -0.38663601
A9: 1Q4 | B9: =Results_from_model!N9 -> -0.063 | C9: =Results_from_model!O9 -> 0.177 | D9: =Results_from_model!P9 -> -0.457 | E9: =Results_from_model!Q9 -> 0.409 | F9: =Results_from_model!R9 -> -0.299 | G9: =Results_from_model!S9 -> 0.341 | H9: =Results_from_model!T9 -> -0.063 | I9: =Results_from_model!U9 -> 0.177 | ... O9: =Results_from_model!AA9 -> 0.31 | AC9: -0.29858589 | AD9: -0.299 | AF9: -0.062858632 | AG9: -0.063 | AI9: -0.30932462 | AJ9: -0.351 | AK9: 0.31 | AL9: -0.299 | AM9: -0.3507807 | AN9: =AM9-N9 -> 0.00021929876 | AO9: -0.31636592 | AP9: -0.29858589 | AQ9: -0.30370513
A10: 2Q1 | B10: =Results_from_model!N10 -> 0.052 | C10: =Results_from_model!O10 -> 0.082 | D10: =Results_from_model!P10 -> -0.356 | E10: =Results_from_model!Q10 -> 0.294 | F10: =Results_from_model!R10 -> -0.195 | G10: =Results_from_model!S10 -> 0.234 | H10: =Results_from_model!T10 -> 0.052 | I10: =Results_from_model!U10 -> 0.082 | ... O10: =Results_from_model!AA10 -> 0.222 | AC10: -0.1947674 | AD10: -0.195 | AF10: 0.052203546 | AG10: 0.052 | AI10: -0.22547745 | AJ10: -0.312 | AK10: 0.222 | AL10: -0.195 | AM10: -0.31180386 | AN10: =AM10-N10 -> 0.00019614223 | AO10: -0.23798404 | AP10: -0.1947674 | AQ10: -0.20983242
A11: 2Q2 | B11: =Results_from_model!N11 -> 0.166 | C11: =Results_from_model!O11 -> 0 | D11: =Results_from_model!P11 -> -0.246 | E11: =Results_from_model!Q11 -> 0.189 | F11: =Results_from_model!R11 -> -0.086 | G11: =Results_from_model!S11 -> 0.137 | H11: =Results_from_model!T11 -> 0.166 | I11: =Results_from_model!U11 -> 0 | ... O11: =Results_from_model!AA11 -> 0.142 | AC11: -0.086050326 | AD11: -0.086 | AF11: 0.1664244 | AG11: 0.166 | AI11: -0.13658261 | AJ11: -0.267 | AK11: 0.142 | AL11: -0.086 | AM11: -0.26725868 | AN11: =AM11-N11 -> -0.00025867745 | AO11: -0.15450031 | AP11: -0.086050326 | AQ11: -0.11099163
A12: 2Q3 | B12: =Results_from_model!N12 -> 0.278 | C12: =Results_from_model!O12 -> -0.069 | D12: =Results_from_model!P12 -> -0.13 | E12: =Results_from_model!Q12 -> 0.096 | F12: =Results_from_model!R12 -> 0.025 | G12: =Results_from_model!S12 -> 0.053 | H12: =Results_from_model!T12 -> 0.278 | I12: =Results_from_model!U12 -> -0.069 | ... O12: =Results_from_model!AA12 -> 0.072 | AC12: 0.025309667 | AD12: 0.025 | AF12: 0.27815626 | AG12: 0.278 | AI12: -0.044717638 | AJ12: -0.219 | AK12: 0.072 | AL12: 0.025 | AM12: -0.21897394 | AN12: =AM12-N12 -> 2.6063488e-05 | AO12: -0.06796681 | AP12: 0.025309667 | AQ12: -0.0093469746
A13: 2Q4 | B13: =Results_from_model!N13 -> 0.387 | C13: =Results_from_model!O13 -> -0.125 | D13: =Results_from_model!P13 -> -0.01 | E13: =Results_from_model!Q13 -> 0.016 | F13: =Results_from_model!R13 -> 0.138 | G13: =Results_from_model!S13 -> -0.019 | H13: =Results_from_model!T13 -> 0.387 | I13: =Results_from_model!U13 -> -0.125 | ... O13: =Results_from_model!AA13 -> 0.012 | AC13: 0.13845113 | AD13: 0.138 | AF13: 0.38689786 | AG13: 0.387 | AI13: 0.049317356 | AJ13: -0.168 | AK13: 0.012 | AL13: 0.138 | AM13: -0.16766294 | AN13: =AM13-N13 -> 0.00033706175 | AO13: 0.02082396 | AP13: 0.13845113 | AQ13: 0.094271423
A14: 3Q1 | B14: =Results_from_model!N14 -> 0.493 | C14: =Results_from_model!O14 -> -0.169 | D14: =Results_from_model!P14 -> 0.116 | E14: =Results_from_model!Q14 -> -0.052 | F14: =Results_from_model!R14 -> 0.253 | G14: =Results_from_model!S14 -> -0.078 | H14: =Results_from_model!T14 -> 0.493 | I14: =Results_from_model!U14 -> -0.169 | ... O14: =Results_from_model!AA14 -> -0.037 | S14: Infrastructure investment | T14: Human capital investment | AC14: 0.25300012 | AD14: 0.253 | AF14: 0.49253816 | AG14: 0.493 | AI14: 0.14517174 | AJ14: -0.114 | AK14: -0.037 | AL14: 0.253 | AM14: -0.11364135 | AN14: =AM14-N14 -> 0.00035865221 | AO14: 0.11152347 | AP14: 0.25300012 | AQ14: 0.19950138
